Workbook
Name _Hlk138419189: 'Mail Dashboard'!$A$53
Name Check10: 'Mail Dashboard'!$A$69
Name Check13: 'Mail Dashboard'!$A$73
Name Check16: 'Mail Dashboard'!$C$76
Name Check17: 'Mail Dashboard'!$B$75
Name Check18: 'Mail Dashboard'!$B$79
Name Check19: 'Mail Dashboard'!$A$81
Name Check20: 'Mail Dashboard'!$D$82
Name Check21: 'Mail Dashboard'!$I$82
Name Check22: 'Mail Dashboard'!$F$83
Name Check23: 'Mail Dashboard'!$H$83
Name Check24: 'Mail Dashboard'!$E$84
Name Check25: 'Mail Dashboard'!$G$84
Name Check26: 'Mail Dashboard'!$A$93
Name Check27: 'Mail Dashboard'!$A$94
Name Check28: 'Mail Dashboard'!$A$95
Name Check29: 'Mail Dashboard'!$A$96
Name Check30: 'Mail Dashboard'!$A$99
Name Check31: 'Mail Dashboard'!$B$99
Name Text10: 'Mail Dashboard'!$B$65
Name Text11: 'Mail Dashboard'!$B$73
Name Text12: 'Mail Dashboard'!$B$81
Name Text18: 'Mail Dashboard'!$B$55
Name Text2: 'Mail Dashboard'!$C$55
Name Text20: 'Mail Dashboard'!$C$93
Name Text21: 'Mail Dashboard'!$E$93
Name Text22: 'Mail Dashboard'!$C$95
Name Text23: 'Mail Dashboard'!$E$96
Name Text24: 'Mail Dashboard'!$C$99

Sheet Pension Calculator
A1: California Ironworkers Field Pension Trust Pension Calculation
A2: Member Name: | C2: Rigoberto Pimentel | H2: Member ID: | I2: 320395X00
A3: Member Date of Birth: | C3: 23105
A4: Member Age at Retirement: | C4: =DATEDIF(C3,C5,"y")&"/"&(DATEDIF(C3,C5, "m") - (DATEDIF(C3,C5, "y") * 12)) -> 62/3
A5: Member Retirement Date: | C5: 45870
A6: Spouse Name: | C6: Perla S. Pimentel | G6: =IF(C7=0,"","Spouse Age Difference from Member:") -> Spouse Age Difference from Member: | J6: =IF(C7=0,"",IF(AND(C3-C7<0,(DATEDIF(C3,C5,"m")-(DATEDIF(C3,C5,"y")*12))-(DATEDIF(C7,C5,"m")-(DATEDIF(C7,C5,"y")*12))=0),DATEDIF(C3,C5,"y")-DATEDIF(C7,C5,"y"),IF(AND(C3-C7>0,(DATEDIF(C7,C5,"m")-(DATEDIF(C7,C5,"y")*12))-(DATEDIF(C3,C5,"m")-(DATEDIF(C3,C5,"y")*12))=0),DATEDIF(C7,C5,"y")-DATEDIF(C3,C5,"y"),IF(C3-C7<0,ROUNDDOWN(YEARFRAC(C3,C7),0),IF(C3-C7>0,ROUNDDOWN(YEARFRAC(C7,C3),0),0))))) -> 8 | K6: =IF(C7=0,"",IF(J6=0,"No Difference.",IF(C3-C7<0,"Year(s) Younger.", IF(C3-C7>0, "Year(s) Older.","No Difference.")))) -> Year(s) Younger.
A7: Spouse Date of Birth: | C7: 26366
A8: =IF(COUNTIF(C7,""),"","Spouse Age at Retirement:") -> Spouse Age at Retirement: | C8: =IF(COUNTIF(C7,""),"",DATEDIF(C7,C5,"y")&"/"&(DATEDIF(C7,C5,"m")-(DATEDIF(C7,C5,"y")*12))) -> 53/4 | D8: 8. Service Pension Pre-Age 55 & Disability Pension
A9: Credits Earned Prior to 09/01/2011 | D9: Benefit Calculation | I9: =IF(COUNTIF(C7,""),"",IF(COUNTIF(D8,"1.*"),"Early Retirement H&W Pension Options",IF(COUNTIF(D8,"2.*"),"Regular at 62 H&W Pension Options",IF(COUNTIF(D8,"3.*"),"Regular at 62 & Early H&W Pension Options",IF(COUNTIF(D8,"4.*"),"Regular at 62 H&W Pension Options",IF(COUNTIF(D8,"5.*"),"Regular at 65 H&W Pension Options",IF(COUNTIF(D8,"6.*"),"Disability H&W Pension Options",IF(COUNTIF(D8,"7.*"),"Service Pre-Age 55 H&W Pension Options",IF(COUNTIF(D8,"8.*"),"Service Pre-Age 55 H&W Pension Options",IF(COUNTIF(D8,"9.*"),"Service H&W Pension Options","Additional H&W Options")))))))))) -> Service Pre-Age 55 H&W Pension Options
A10: CA Credits | B10: Rate | C10: Value | D10: Total Pension Credits | H10: =SUM(A11:A17,A20:A21,A24:A29) -> 7.33 | I10: =IF(COUNTIF(C7,""),"","Option") -> Option | J10: =IF(COUNTIF(C7,""),"","Factor") -> Factor | K10: =IF(COUNTIF(C7,""),"","Member Benefit") -> Member Benefit | L10: =IF(COUNTIF(C7,""),"","Spouse Benefit") -> Spouse Benefit
C11: =A11*B11 -> 0 | D11: Member Benefit Prior to 09/01/2011 | G11: =SUM(A11:A17) -> 7.33 | H11: =C18 -> 876 | I11: =IF(COUNTIF(C7,""),"","50%") -> 50% | J11: =IF(COUNTIF(C7,""),"",IF(COUNTIF(D8,"4.*"),IF(COUNTIF(K6,"*Younger*"),100%-8%-(J6*0.4%),IF(100%-8%+(J6*0.4%)>100%,100%,100%-8%+(J6*0.4%)))*100&"% / "&IF(COUNTIF(K6,"*Younger*"),100%-18%-(J6*0.4%),IF(100%-18%+(J6*0.4%)>100%,100%,100%-18%+(J6*0.4%)))*100&"%",IF(COUNTIF(D8,"6.*"),IF(COUNTIF(K6,"*Younger*"),100%-18%-(J6*0.4%),IF(100%-18%+(J6*0.4%)>100%,100%,100%-18%+(J6*0.4%))),IF(COUNTIF(D8,"8.*"),IF(COUNTIF(K6,"*Younger*"),100%-8%-(J6*0.4%),IF(100%-8%+(J6*0.4%)>100%,100%,100%-8%+(J6*0.4%)))*100&"% / "&IF(COUNTIF(K6,"*Younger*"),100%-18%-(J6*0.4%),IF(100%-18%+(J6*0.4%)>100%,100%,100%-18%+(J6*0.4%)))*100&"%",IF(COUNTIF(K6,"*Younger*"),100%-8%-(J6*0.4%),IF(100%-8%+(J6*0.4%)>100%,100%,100%-8%+(J6*0.4%))))))) -> 88.8% / 78.8% | K11: =IF(COUNTIF(C7,""),"",IF(COUNTIF(D8,"1.*"),(H13+H16+H19)*J11,IF(COUNTIF(D8,"2.*"),(H11)*J11,IF(COUNTIF(D8,"3.*"),(H11+H16+H19)*J11,IF(COUNTIF(D8,"5.*"),(H11+H14+H17)*J11,IF(COUNTIF(D8,"6.*"),(H11+H14+H17)*J11,IF(COUNTIF(D8,"7.*"),(H11+H14)*J11,IF(COUNTIF(D8,"8.*"),(H11+H14)*IF(COUNTIF(K6,"*Younger*"),100%-8%-(J6*0.4%),IF(100%-8%+(J6*0.4%)>100%,100%,100%-8%+(J6*0.4%)))+(H17*IF(COUNTIF(K6,"*Younger*"),100%-18%-(J6*0.4%),IF(100%-18%+(J6*0.4%)>100%,100%,100%-18%+(J6*0.4%)))),IF(COUNTIF(D8,"4.*"),H11*IF(COUNTIF(K6,"*Younger*"),100%-8%-(J6*0.4%),IF(100%-8%+(J6*0.4%)>100%,100%,100%-8%+(J6*0.4%)))+(H14+H17)*IF(COUNTIF(K6,"*Younger*"),100%-18%-(J6*0.4%),IF(100%-18%+(J6*0.4%)>100%,100%,100%-18%+(J6*0.4%))),IF(COUNTIF(D8,"9.*"),(H11+H14+H17)*J11,"")))))))))) -> 777.888 | L11: =IF(COUNTIF(C7,""),"",K11*I11) -> 388.944
C12: =A12*B12 -> 0 | D12: =IF(COUNTIF(D8,"1.*"),"ER Factor","") | H12: =IF(COUNTIF(D8,"1.*"),IF(DATEDIF(C3,C5,"m")<=600,(DATEDIF(C3,C5,"m")-540)*0.1%+40%,IF(DATEDIF(C3,C5,"m")<=660,(DATEDIF(C3,C5,"m")-600)*0.2%+46%,IF((DATEDIF(C3,C5,"m")-660)*0.5%+58%>=100%,100%,(DATEDIF(C3,C5,"m")-660)*0.5%+58%))),"") | I12: =IF(COUNTIF(C7,""),"","13th Check") -> 13th Check | J12: =IF(COUNTIF(C7,""),"",IF(COUNTIF(D8,"4.*"),IF(COUNTIF(K6,"*Younger*"),100%-8%-(J6*0.4%),IF(100%-8%+(J6*0.4%)>100%,100%,100%-8%+(J6*0.4%)))*100&"% / "&IF(COUNTIF(K6,"*Younger*"),100%-18%-(J6*0.4%),IF(100%-18%+(J6*0.4%)>100%,100%,100%-18%+(J6*0.4%)))*100&"%",IF(COUNTIF(D8,"6.*"),IF(COUNTIF(K6,"*Younger*"),100%-18%-(J6*0.4%),IF(100%-18%+(J6*0.4%)>100%,100%,100%-18%+(J6*0.4%))),IF(COUNTIF(D8,"8.*"),IF(COUNTIF(K6,"*Younger*"),100%-8%-(J6*0.4%),IF(100%-8%+(J6*0.4%)>100%,100%,100%-8%+(J6*0.4%)))*100&"% / "&IF(COUNTIF(K6,"*Younger*"),100%-18%-(J6*0.4%),IF(100%-18%+(J6*0.4%)>100%,100%,100%-18%+(J6*0.4%)))*100&"%",IF(COUNTIF(K6,"*Younger*"),100%-8%-(J6*0.4%),IF(100%-8%+(J6*0.4%)>100%,100%,100%-8%+(J6*0.4%))))))) -> 88.8% / 78.8% | K12: =IF(COUNTIF(C7,""),"",IF(COUNTIF(D8,"1.*"),(H13+H16+H19)*J12,IF(COUNTIF(D8,"2.*"),(H11)*J12,IF(COUNTIF(D8,"3.*"),(H11+H16+H19)*J12,IF(COUNTIF(D8,"5.*"),(H11+H14+H17)*J12,IF(COUNTIF(D8,"6.*"),(H11+H14+H17)*J12,IF(COUNTIF(D8,"7.*"),(H11+H14)*J12,IF(COUNTIF(D8,"8.*"),(H11+H14)*IF(COUNTIF(K6,"*Younger*"),100%-8%-(J6*0.4%),IF(100%-8%+(J6*0.4%)>100%,100%,100%-8%+(J6*0.4%)))+(H17*IF(COUNTIF(K6,"*Younger*"),100%-18%-(J6*0.4%),IF(100%-18%+(J6*0.4%)>100%,100%,100%-18%+(J6*0.4%)))),IF(COUNTIF(D8,"4.*"),H11*IF(COUNTIF(K6,"*Younger*"),100%-8%-(J6*0.4%),IF(100%-8%+(J6*0.4%)>100%,100%,100%-8%+(J6*0.4%)))+(H14+H17)*IF(COUNTIF(K6,"*Younger*"),100%-18%-(J6*0.4%),IF(100%-18%+(J6*0.4%)>100%,100%,100%-18%+(J6*0.4%))),IF(COUNTIF(D8,"9.*"),(H11+H14+H17)*J12,"")))))))))) -> 777.888 | L12: =IF(COUNTIF(C7,""),"",K12*I11) -> 388.944
C13: =A13*B13 -> 0 | D13: =IF(COUNTIF(D8,"1.*"),"ER Benefit Prior to 09/01/2011","") | H13: =IF(COUNTIF(D8,"1.*"),(H11*H12),"") | I13: =IF(COUNTIF(C7,""),"","75%") -> 75% | J13: =IF(COUNTIF(C7,""),"",IF(COUNTIF(D8,"4.*"),IF(COUNTIF(K6,"*Younger*"),100%-12%-(J6*0.4%),IF(100%-12%+(J6*0.4%)>100%,100%,100%-12%+(J6*0.4%)))*100&"% / "&IF(COUNTIF(K6,"*Younger*"),100%-24%-(J6*0.4%),IF(100%-24%+(J6*0.4%)>100%,100%,100%-24%+(J6*0.4%)))*100&"%",IF(COUNTIF(D8,"6.*"),IF(COUNTIF(K6,"*Younger*"),100%-24%-(J6*0.4%),IF(100%-24%+(J6*0.4%)>100%,100%,100%-24%+(J6*0.4%))),IF(COUNTIF(D8,"8.*"),IF(COUNTIF(K6,"*Younger*"),100%-12%-(J6*0.4%),IF(100%-12%+(J6*0.4%)>100%,100%,100%-12%+(J6*0.4%)))*100&"% / "&IF(COUNTIF(K6,"*Younger*"),100%-24%-(J6*0.4%),IF(100%-24%+(J6*0.4%)>100%,100%,100%-24%+(J6*0.4%)))*100&"%",IF(COUNTIF(K6,"*Younger*"),100%-12%-(J6*0.4%),IF(100%-12%+(J6*0.4%)>100%,100%,100%-12%+(J6*0.4%))))))) -> 84.8% / 72.8% | K13: =IF(COUNTIF(C7,""),"",IF(COUNTIF(D8,"1.*"),(H13+H16+H19)*J13,IF(COUNTIF(D8,"2.*"),(H11)*J13,IF(COUNTIF(D8,"3.*"),(H11+H16+H19)*J13,IF(COUNTIF(D8,"5.*"),(H11+H14+H17)*J13,IF(COUNTIF(D8,"6.*"),(H11+H14+H17)*J13,IF(COUNTIF(D8,"7.*"),(H11+H14)*J13,IF(COUNTIF(D8,"8.*"),(H11+H14)*IF(COUNTIF(K6,"*Younger*"),100%-12%-(J6*0.4%),IF(100%-12%+(J6*0.4%)>100%,100%,100%-12%+(J6*0.4%)))+(H17*IF(COUNTIF(K6,"*Younger*"),100%-24%-(J6*0.4%),IF(100%-24%+(J6*0.4%)>100%,100%,100%-24%+(J6*0.4%)))),IF(COUNTIF(D8,"4.*"),H11*IF(COUNTIF(K6,"*Younger*"),100%-12%-(J6*0.4%),IF(100%-12%+(J6*0.4%)>100%,100%,100%-12%+(J6*0.4%)))+(H14+H17)*IF(COUNTIF(K6,"*Younger*"),100%-24%-(J6*0.4%),IF(100%-24%+(J6*0.4%)>100%,100%,100%-24%+(J6*0.4%))),IF(COUNTIF(D8,"9.*"),(H11+H14+H17)*J13,"")))))))))) -> 742.848 | L13: =IF(COUNTIF(C7,""),"",K13*I13) -> 557.136
B14: 50 | C14: =A14*B14 -> 0 | D14: ="Member Benefit from 09/01/2011 to 09/30/2014" -> Member Benefit from 09/01/2011 to 09/30/2014 | G14: =SUM(A20:A21) -> 0 | H14: =C22 -> 0 | I14: =IF(COUNTIF(C7,""),"","13th Check") -> 13th Check | J14: =IF(COUNTIF(C7,""),"",IF(COUNTIF(D8,"4.*"),IF(COUNTIF(K6,"*Younger*"),100%-12%-(J6*0.4%),IF(100%-12%+(J6*0.4%)>100%,100%,100%-12%+(J6*0.4%)))*100&"% / "&IF(COUNTIF(K6,"*Younger*"),100%-24%-(J6*0.4%),IF(100%-24%+(J6*0.4%)>100%,100%,100%-24%+(J6*0.4%)))*100&"%",IF(COUNTIF(D8,"6.*"),IF(COUNTIF(K6,"*Younger*"),100%-24%-(J6*0.4%),IF(100%-24%+(J6*0.4%)>100%,100%,100%-24%+(J6*0.4%))),IF(COUNTIF(D8,"8.*"),IF(COUNTIF(K6,"*Younger*"),100%-12%-(J6*0.4%),IF(100%-12%+(J6*0.4%)>100%,100%,100%-12%+(J6*0.4%)))*100&"% / "&IF(COUNTIF(K6,"*Younger*"),100%-24%-(J6*0.4%),IF(100%-24%+(J6*0.4%)>100%,100%,100%-24%+(J6*0.4%)))*100&"%",IF(COUNTIF(K6,"*Younger*"),100%-12%-(J6*0.4%),IF(100%-12%+(J6*0.4%)>100%,100%,100%-12%+(J6*0.4%))))))) -> 84.8% / 72.8% | K14: =IF(COUNTIF(C7,""),"",IF(COUNTIF(D8,"1.*"),(H13+H16+H19)*J14,IF(COUNTIF(D8,"2.*"),(H11)*J14,IF(COUNTIF(D8,"3.*"),(H11+H16+H19)*J14,IF(COUNTIF(D8,"5.*"),(H11+H14+H17)*J14,IF(COUNTIF(D8,"6.*"),(H11+H14+H17)*J14,IF(COUNTIF(D8,"7.*"),(H11+H14)*J14,IF(COUNTIF(D8,"8.*"),(H11+H14)*IF(COUNTIF(K6,"*Younger*"),100%-12%-(J6*0.4%),IF(100%-12%+(J6*0.4%)>100%,100%,100%-12%+(J6*0.4%)))+(H17*IF(COUNTIF(K6,"*Younger*"),100%-24%-(J6*0.4%),IF(100%-24%+(J6*0.4%)>100%,100%,100%-24%+(J6*0.4%)))),IF(COUNTIF(D8,"4.*"),H11*IF(COUNTIF(K6,"*Younger*"),100%-12%-(J6*0.4%),IF(100%-12%+(J6*0.4%)>100%,100%,100%-12%+(J6*0.4%)))+(H14+H17)*IF(COUNTIF(K6,"*Younger*"),100%-24%-(J6*0.4%),IF(100%-24%+(J6*0.4%)>100%,100%,100%-24%+(J6*0.4%))),IF(COUNTIF(D8,"9.*"),(H11+H14+H17)*J14,"")))))))))) -> 742.848 | L14: =IF(COUNTIF(C7,""),"",K14*I13) -> 557.136
A15: 5.75 | B15: 118 | C15: =A15*B15 -> 678.5 | D15: =IF(OR(COUNTIF(D8,"1.*"),COUNTIF(D8,"2.*"),COUNTIF(D8,"3.*")),"ER Factor","") | H15: =IF(OR(COUNTIF(D8,"1.*"),COUNTIF(D8,"2.*"),COUNTIF(D8,"3.*")),IF(DATEDIF(C3,C5,"m")<=600,(DATEDIF(C3,C5,"m")-540)*0.1%+22%,IF(DATEDIF(C3,C5,"m")<=660,(DATEDIF(C3,C5,"m")-600)*0.2%+28%,IF((DATEDIF(C3,C5,"m")-660)*0.5%+40%>=100%,100%,(DATEDIF(C3,C5,"m")-660)*0.5%+40%))),"") | I15: =IF(COUNTIF(C7,""),"","100%") -> 100% | J15: =IF(COUNTIF(C7,""),"",IF(COUNTIF(D8,"4.*"),IF(COUNTIF(K6,"*Younger*"),100%-15%-(J6*0.5%),IF(100%-15%+(J6*0.5%)>100%,100%,100%-15%+(J6*0.5%)))*100&"% / "&IF(COUNTIF(K6,"*Younger*"),100%-30%-(J6*0.5%),IF(100%-30%+(J6*0.5%)>100%,100%,100%-30%+(J6*0.5%)))*100&"%",IF(COUNTIF(D8,"6.*"),IF(COUNTIF(K6,"*Younger*"),100%-30%-(J6*0.5%),IF(100%-30%+(J6*0.5%)>100%,100%,100%-30%+(J6*0.5%))),IF(COUNTIF(D8,"8.*"),IF(COUNTIF(K6,"*Younger*"),100%-15%-(J6*0.5%),IF(100%-15%+(J6*0.5%)>100%,100%,100%-15%+(J6*0.5%)))*100&"% / "&IF(COUNTIF(K6,"*Younger*"),100%-30%-(J6*0.5%),IF(100%-30%+(J6*0.5%)>100%,100%,100%-30%+(J6*0.5%)))*100&"%",IF(COUNTIF(K6,"*Younger*"),100%-15%-(J6*0.5%),IF(100%-15%+(J6*0.5%)>100%,100%,100%-15%+(J6*0.5%))))))) -> 81% / 66% | K15: =IF(COUNTIF(C7,""),"",IF(COUNTIF(D8,"1.*"),(H13+H16+H19)*J15,IF(COUNTIF(D8,"2.*"),(H11)*J15,IF(COUNTIF(D8,"3.*"),(H11+H16+H19)*J15,IF(COUNTIF(D8,"5.*"),(H11+H14+H17)*J15,IF(COUNTIF(D8,"6.*"),(H11+H14+H17)*J15,IF(COUNTIF(D8,"7.*"),(H11+H14)*J15,IF(COUNTIF(D8,"8.*"),(H11+H14)*IF(COUNTIF(K6,"*Younger*"),100%-15%-(J6*0.5%),IF(100%-15%+(J6*0.5%)>100%,100%,100%-15%+(J6*0.5%)))+(H17*IF(COUNTIF(K6,"*Younger*"),100%-30%-(J6*0.5%),IF(100%-30%+(J6*0.5%)>100%,100%,100%-30%+(J6*0.5%)))),IF(COUNTIF(D8,"4.*"),H11*IF(COUNTIF(K6,"*Younger*"),100%-15%-(J6*0.5%),IF(100%-15%+(J6*0.5%)>100%,100%,100%-15%+(J6*0.5%)))+(H14+H17)*IF(COUNTIF(K6,"*Younger*"),100%-30%-(J6*0.5%),IF(100%-30%+(J6*0.5%)>100%,100%,100%-30%+(J6*0.5%))),IF(COUNTIF(D8,"9.*"),(H11+H14+H17)*J15,"")))))))))) -> 709.56 | L15: =IF(COUNTIF(C7,""),"",K15*I15) -> 709.56
B16: 105 | C16: =A16*B16 -> 0 | D16: =IF(OR(COUNTIF(D8,"1.*"),COUNTIF(D8,"2.*"),COUNTIF(D8,"3.*")),"ER Benefit from 09/01/2011 to 09/30/2014","") | H16: =IF(OR(COUNTIF(D8,"1.*"),COUNTIF(D8,"2.*"),COUNTIF(D8,"3.*")),H14*H15,"") | I16: =IF(COUNTIF(C7,""),"","13th Check") -> 13th Check | J16: =IF(COUNTIF(C7,""),"",IF(COUNTIF(D8,"4.*"),IF(COUNTIF(K6,"*Younger*"),100%-15%-(J6*0.5%),IF(100%-15%+(J6*0.5%)>100%,100%,100%-15%+(J6*0.5%)))*100&"% / "&IF(COUNTIF(K6,"*Younger*"),100%-30%-(J6*0.5%),IF(100%-30%+(J6*0.5%)>100%,100%,100%-30%+(J6*0.5%)))*100&"%",IF(COUNTIF(D8,"6.*"),IF(COUNTIF(K6,"*Younger*"),100%-30%-(J6*0.5%),IF(100%-30%+(J6*0.5%)>100%,100%,100%-30%+(J6*0.5%))),IF(COUNTIF(D8,"8.*"),IF(COUNTIF(K6,"*Younger*"),100%-15%-(J6*0.5%),IF(100%-15%+(J6*0.5%)>100%,100%,100%-15%+(J6*0.5%)))*100&"% / "&IF(COUNTIF(K6,"*Younger*"),100%-30%-(J6*0.5%),IF(100%-30%+(J6*0.5%)>100%,100%,100%-30%+(J6*0.5%)))*100&"%",IF(COUNTIF(K6,"*Younger*"),100%-15%-(J6*0.5%),IF(100%-15%+(J6*0.5%)>100%,100%,100%-15%+(J6*0.5%))))))) -> 81% / 66% | K16: =IF(COUNTIF(C7,""),"",IF(COUNTIF(D8,"1.*"),(H13+H16+H19)*J16,IF(COUNTIF(D8,"2.*"),(H11)*J16,IF(COUNTIF(D8,"3.*"),(H11+H16+H19)*J16,IF(COUNTIF(D8,"5.*"),(H11+H14+H17)*J16,IF(COUNTIF(D8,"6.*"),(H11+H14+H17)*J16,IF(COUNTIF(D8,"7.*"),(H11+H14)*J16,IF(COUNTIF(D8,"8.*"),(H11+H14)*IF(COUNTIF(K6,"*Younger*"),100%-15%-(J6*0.5%),IF(100%-15%+(J6*0.5%)>100%,100%,100%-15%+(J6*0.5%)))+(H17*IF(COUNTIF(K6,"*Younger*"),100%-30%-(J6*0.5%),IF(100%-30%+(J6*0.5%)>100%,100%,100%-30%+(J6*0.5%)))),IF(COUNTIF(D8,"4.*"),H11*IF(COUNTIF(K6,"*Younger*"),100%-15%-(J6*0.5%),IF(100%-15%+(J6*0.5%)>100%,100%,100%-15%+(J6*0.5%)))+(H14+H17)*IF(COUNTIF(K6,"*Younger*"),100%-30%-(J6*0.5%),IF(100%-30%+(J6*0.5%)>100%,100%,100%-30%+(J6*0.5%))),IF(COUNTIF(D8,"9.*"),(H11+H14+H17)*J16,"")))))))))) -> 709.56 | L16: =IF(COUNTIF(C7,""),"",K16*I15) -> 709.56
A17: 1.58 | B17: 125 | C17: =A17*B17 -> 197.5 | D17: ="Member Benefit on and After 10/01/2014" -> Member Benefit on and After 10/01/2014 | G17: =SUM(A24:A29) -> 0 | H17: =C30 -> 0
A18: =SUM(A11:A17) -> 7.33 | B18: Subtotal | C18: =SUM(C11:C17) -> 876 | D18: =IF(OR(COUNTIF(D8,"1.*"),COUNTIF(D8,"2.*"),COUNTIF(D8,"3.*"),COUNTIF(D8,"7.*")),"ER Factor","") | H18: =IF(OR(COUNTIF(D8,"1.*"),COUNTIF(D8,"2.*"),COUNTIF(D8,"3.*"),COUNTIF(D8,"7.*")),IF(DATEDIF(C3,C5,"m")<=600,(DATEDIF(C3,C5,"m")-540)*0.1%+22%,IF(DATEDIF(C3,C5,"m")<=660,(DATEDIF(C3,C5,"m")-600)*0.2%+28%,IF((DATEDIF(C3,C5,"m")-660)*0.5%+40%>=100%,100%,(DATEDIF(C3,C5,"m")-660)*0.5%+40%))),"") | I18: =IF(COUNTIF(C7,""),"",IF(COUNTIF(D8,"1.*"),"Pension Benefit Deferred at Age 65 H&W Options",IF(COUNTIF(D8,"2.*"),"Regular at 62 & Early H&W Options",IF(OR(COUNTIF(D8,"3.*"),COUNTIF(D8,"7.*")),"Pension Benefit Regular at 62 with Early H&W Options",IF(COUNTIF(D8,"4.*"),"Disability after 09/01/2011 H&W Options",IF(COUNTIF(D8,"8.*"),"Disability after 10/01/2014 H&W Options","")))))) -> Disability after 10/01/2014 H&W Options
A19: Credits Earned On or After 09/01/2011 | D19: =IF(OR(COUNTIF(D8,"1.*"),COUNTIF(D8,"2.*"),COUNTIF(D8,"3.*"),COUNTIF(D8,"7.*")),"ER Benefit on or After 10/01/2014","") | H19: =IF(OR(COUNTIF(D8,"1.*"),COUNTIF(D8,"2.*"),COUNTIF(D8,"3.*"),COUNTIF(D8,"7.*")),H17*H18,"") | I19: =IF(COUNTIF(C7,""),"",IF(OR(COUNTIF(D8,"1.*"),COUNTIF(D8,"2.*"),COUNTIF(D8,"3.*"),COUNTIF(D8,"7.*"),COUNTIF(D8,"8.*")),"Option","")) -> Option | J19: =IF(COUNTIF(C7,""),"",IF(OR(COUNTIF(D8,"1.*"),COUNTIF(D8,"2.*"),COUNTIF(D8,"3.*"),COUNTIF(D8,"7.*"),COUNTIF(D8,"8.*")),"Factor","")) -> Factor | K19: =IF(COUNTIF(C7,""),"",IF(OR(COUNTIF(D8,"1.*"),COUNTIF(D8,"2.*"),COUNTIF(D8,"3.*"),COUNTIF(D8,"7.*"),COUNTIF(D8,"8.*")),"Member Benefit","")) -> Member Benefit | L19: =IF(COUNTIF(C7,""),"",IF(OR(COUNTIF(D8,"1.*"),COUNTIF(D8,"2.*"),COUNTIF(D8,"3.*"),COUNTIF(D8,"7.*"),COUNTIF(D8,"8.*")),"Spouse Benefit","")) -> Spouse Benefit
B20: 90 | C20: =A20*B20 -> 0 | I20: =IF(COUNTIF(C7,""),"",IF(OR(COUNTIF(D8,"1.*"),COUNTIF(D8,"2.*"),COUNTIF(D8,"3.*"),COUNTIF(D8,"7.*"),COUNTIF(D8,"8.*")),"50%","")) -> 50% | J20: =IF(COUNTIF(C7,""),"",IF(OR(COUNTIF(D8,"1.*"),COUNTIF(D8,"2.*"),COUNTIF(D8,"3.*"),COUNTIF(D8,"7.*")),IF(COUNTIF(K6,"*Younger*"),100%-8%-(J6*0.4%),IF(100%-8%+(J6*0.4%)>100%,100%,100%-8%+(J6*0.4%))),IF(OR(COUNTIF(D8,"4.*"),COUNTIF(D8,"8.*")),IF(COUNTIF(K6,"*Younger*"),100%-18%-(J6*0.4%),IF(100%-18%+(J6*0.4%)>100%,100%,100%-18%+(J6*0.4%))),""))) -> 0.788 | K20: =IF(COUNTIF(C7,""),"",IF(COUNTIF(D8,"1.*"),(H27*J20),IF(COUNTIF(D8,"2.*"),(H11+H16+H19)*J20,IF(COUNTIF(D8,"3.*"),(H11+H14+H17)*J20,IF(COUNTIF(D8,"7.*"),(H11+H14+H19)*J20,""))))) | L20: =IF(COUNTIF(C7,""),"",IF(OR(COUNTIF(D8,"1.*"),COUNTIF(D8,"2.*"),COUNTIF(D8,"3.*"),COUNTIF(D8,"7.*")),K20*I20,""))
B21: 125 | C21: =A21*B21 -> 0 | D21: =IF(COUNTIF(D8,"1.*"),"Member Early Retirement Pension Amount",IF(COUNTIF(D8,"2.*"),"Member Regular Retirement Pension at 62 Amount",IF(COUNTIF(D8,"3.*"),"Member Regular at 62 & Early Retirement Pension Amount",IF(COUNTIF(D8,"4.*"),"Member Regular Retirement at 62 & Disability Pension Amount",IF(COUNTIF(D8,"5.*"),"Member Regular Retirement Pension at 65 Amount",IF(COUNTIF(D8,"6.*"),"Member Disability Pension Amount",IF(COUNTIF(D8,"7.*"),"Member Pre-Age 55 Service",IF(COUNTIF(D8,"8.*"),"Member Pre-Age 55 Service & Disability Pension Amount",IF(COUNTIF(D8,"9.*"),"Member Service Pension Amount",""))))))))) -> Member Pre-Age 55 Service & Disability Pension Amount | H21: =IF(COUNTIF(D8,"1.*"),SUM(H13,H16,H19),IF(COUNTIF(D8,"2.*"),H11,IF(COUNTIF(D8,"3.*"),SUM(H11,H16,H19),IF(COUNTIF(D8,"4.*"),SUM(H11,H14,H17),IF(COUNTIF(D8,"5.*"),SUM(H11,H14,H17),IF(COUNTIF(D8,"6.*"),SUM(H11,H14,H17),IF(COUNTIF(D8,"7.*"),SUM(H11,H14),IF(COUNTIF(D8,"8.*"),SUM(H11,H14,H17),IF(COUNTIF(D8,"9.*"),SUM(H11,H14,H17),""))))))))) -> 876 | I21: =IF(COUNTIF(C7,""),"",IF(OR(COUNTIF(D8,"1.*"),COUNTIF(D8,"2.*"),COUNTIF(D8,"3.*"),COUNTIF(D8,"7.*"),COUNTIF(D8,"8.*")),"13th Check","")) -> 13th Check | J21: =IF(COUNTIF(C7,""),"",IF(OR(COUNTIF(D8,"1.*"),COUNTIF(D8,"2.*"),COUNTIF(D8,"3.*"),COUNTIF(D8,"7.*")),IF(COUNTIF(K6,"*Younger*"),100%-8%-(J6*0.4%),IF(100%-8%+(J6*0.4%)>100%,100%,100%-8%+(J6*0.4%))),IF(OR(COUNTIF(D8,"4.*"),COUNTIF(D8,"8.*")),IF(COUNTIF(K6,"*Younger*"),100%-18%-(J6*0.4%),IF(100%-18%+(J6*0.4%)>100%,100%,100%-18%+(J6*0.4%))),""))) -> 0.788 | K21: =IF(COUNTIF(C7,""),"",IF(COUNTIF(D8,"1.*"),(H27*J21),IF(COUNTIF(D8,"2.*"),(H11+H16+H19)*J21,IF(COUNTIF(D8,"3.*"),(H11+H14+H17)*J21,IF(COUNTIF(D8,"7.*"),(H11+H14+H19)*J21,""))))) | L21: =IF(COUNTIF(C7,""),"",IF(OR(COUNTIF(D8,"1.*"),COUNTIF(D8,"2.*"),COUNTIF(D8,"3.*"),COUNTIF(D8,"7.*")),K21*I20,""))
A22: =SUM(A20:A21) -> 0 | B22: Subtotal | C22: =SUM(C20:C21) -> 0 | D22: Member 13th Check | H22: =IF(COUNTIF(D8,"1.*"),SUM(H13,H16,H19),IF(COUNTIF(D8,"2.*"),H11,IF(COUNTIF(D8,"3.*"),SUM(H11,H16,H19),IF(COUNTIF(D8,"4.*"),SUM(H11,H14,H17),IF(COUNTIF(D8,"5.*"),SUM(H11,H14,H17),IF(COUNTIF(D8,"6.*"),SUM(H11,H14,H17),IF(COUNTIF(D8,"7.*"),SUM(H11,H14),IF(COUNTIF(D8,"8.*"),SUM(H11,H14,H17),IF(COUNTIF(D8,"9.*"),SUM(H11,H14,H17),""))))))))) -> 876 | I22: =IF(COUNTIF(C7,""),"",IF(OR(COUNTIF(D8,"1.*"),COUNTIF(D8,"2.*"),COUNTIF(D8,"3.*"),COUNTIF(D8,"7.*"),COUNTIF(D8,"8.*")),"75%","")) -> 75% | J22: =IF(COUNTIF(C7,""),"",IF(OR(COUNTIF(D8,"1.*"),COUNTIF(D8,"2.*"),COUNTIF(D8,"3.*"),COUNTIF(D8,"7.*")),IF(COUNTIF(K6,"*Younger*"),100%-12%-(J6*0.4%),IF(100%-12%+(J6*0.4%)>100%,100%,100%-12%+(J6*0.4%))),IF(OR(COUNTIF(D8,"4.*"),COUNTIF(D8,"8.*")),IF(COUNTIF(K6,"*Younger*"),100%-24%-(J6*0.4%),IF(100%-24%+(J6*0.4%)>100%,100%,100%-24%+(J6*0.4%))),""))) -> 0.728 | K22: =IF(COUNTIF(C7,""),"",IF(COUNTIF(D8,"1.*"),(H27*J22),IF(COUNTIF(D8,"2.*"),(H11+H16+H19)*J22,IF(COUNTIF(D8,"3.*"),(H11+H14+H17)*J22,IF(COUNTIF(D8,"7.*"),(H11+H14+H19)*J22,""))))) | L22: =IF(COUNTIF(C7,""),"",IF(OR(COUNTIF(D8,"1.*"),COUNTIF(D8,"2.*"),COUNTIF(D8,"3.*"),COUNTIF(D8,"7.*")),K22*I22,""))
A23: Credits Earned On or After 10/01/2014 | I23: =IF(COUNTIF(C7,""),"",IF(OR(COUNTIF(D8,"1.*"),COUNTIF(D8,"2.*"),COUNTIF(D8,"3.*"),COUNTIF(D8,"7.*"),COUNTIF(D8,"8.*")),"13th Check","")) -> 13th Check | J23: =IF(COUNTIF(C7,""),"",IF(OR(COUNTIF(D8,"1.*"),COUNTIF(D8,"2.*"),COUNTIF(D8,"3.*"),COUNTIF(D8,"7.*")),IF(COUNTIF(K6,"*Younger*"),100%-12%-(J6*0.4%),IF(100%-12%+(J6*0.4%)>100%,100%,100%-12%+(J6*0.4%))),IF(OR(COUNTIF(D8,"4.*"),COUNTIF(D8,"8.*")),IF(COUNTIF(K6,"*Younger*"),100%-24%-(J6*0.4%),IF(100%-24%+(J6*0.4%)>100%,100%,100%-24%+(J6*0.4%))),""))) -> 0.728 | K23: =IF(COUNTIF(C7,""),"",IF(COUNTIF(D8,"1.*"),(H27*J23),IF(COUNTIF(D8,"2.*"),(H11+H16+H19)*J23,IF(COUNTIF(D8,"3.*"),(H11+H14+H17)*J23,IF(COUNTIF(D8,"7.*"),(H11+H14+H19)*J23,""))))) | L23: =IF(COUNTIF(C7,""),"",IF(OR(COUNTIF(D8,"1.*"),COUNTIF(D8,"2.*"),COUNTIF(D8,"3.*"),COUNTIF(D8,"7.*")),K23*I22,""))
B24: 105 | C24: =A24*B24 -> 0 | D24: =IF(COUNTIF(D8,"2.*"),"Member Regular Retirement Pension at 62 with Early",IF(COUNTIF(D8,"7.*"),"Member Service Pension Pre-Age 55 with Early","")) | H24: =IF(COUNTIF(D8,"2.*"),H11+H16+H19,IF(COUNTIF(D8,"7.*"),H11+H14+H19,"")) | I24: =IF(COUNTIF(C7,""),"",IF(OR(COUNTIF(D8,"1.*"),COUNTIF(D8,"2.*"),COUNTIF(D8,"3.*"),COUNTIF(D8,"7.*"),COUNTIF(D8,"8.*")),"100%","")) -> 100% | J24: =IF(COUNTIF(C7,""),"",IF(OR(COUNTIF(D8,"1.*"),COUNTIF(D8,"2.*"),COUNTIF(D8,"3.*"),COUNTIF(D8,"7.*")),IF(COUNTIF(K6,"*Younger*"),100%-15%-(J6*0.5%),IF(100%-15%+(J6*0.5%)>100%,100%,100%-15%+(J6*0.5%))),IF(OR(COUNTIF(D8,"4.*"),COUNTIF(D8,"8.*")),IF(COUNTIF(K6,"*Younger*"),100%-30%-(J6*0.5%),IF(100%-30%+(J6*0.5%)>100%,100%,100%-30%+(J6*0.5%))),""))) -> 0.66 | K24: =IF(COUNTIF(C7,""),"",IF(COUNTIF(D8,"1.*"),(H27*J24),IF(COUNTIF(D8,"2.*"),(H11+H16+H19)*J24,IF(COUNTIF(D8,"3.*"),(H11+H14+H17)*J24,IF(COUNTIF(D8,"7.*"),(H11+H14+H19)*J24,""))))) | L24: =IF(COUNTIF(C7,""),"",IF(OR(COUNTIF(D8,"1.*"),COUNTIF(D8,"2.*"),COUNTIF(D8,"3.*"),COUNTIF(D8,"7.*")),K24*I24,""))
B25: 125 | C25: =A25*B25 -> 0 | D25: =IF(OR(COUNTIF(D8,"2.*"),COUNTIF(D8,"7.*")),"Member 13th Check","") | H25: =IF(COUNTIF(D8,"2.*"),H11+H16+H19,IF(COUNTIF(D8,"7.*"),H11+H14+H19,"")) | I25: =IF(COUNTIF(C7,""),"",IF(OR(COUNTIF(D8,"1.*"),COUNTIF(D8,"2.*"),COUNTIF(D8,"3.*"),COUNTIF(D8,"7.*"),COUNTIF(D8,"8.*")),"13th Check","")) -> 13th Check | J25: =IF(COUNTIF(C7,""),"",IF(OR(COUNTIF(D8,"1.*"),COUNTIF(D8,"2.*"),COUNTIF(D8,"3.*"),COUNTIF(D8,"7.*")),IF(COUNTIF(K6,"*Younger*"),100%-15%-(J6*0.5%),IF(100%-15%+(J6*0.5%)>100%,100%,100%-15%+(J6*0.5%))),IF(OR(COUNTIF(D8,"4.*"),COUNTIF(D8,"8.*")),IF(COUNTIF(K6,"*Younger*"),100%-30%-(J6*0.5%),IF(100%-30%+(J6*0.5%)>100%,100%,100%-30%+(J6*0.5%))),""))) -> 0.66 | K25: =IF(COUNTIF(C7,""),"",IF(COUNTIF(D8,"1.*"),(H27*J25),IF(COUNTIF(D8,"2.*"),(H11+H16+H19)*J25,IF(COUNTIF(D8,"3.*"),(H11+H14+H17)*J25,IF(COUNTIF(D8,"7.*"),(H11+H14+H19)*J25,""))))) | L25: =IF(COUNTIF(C7,""),"",IF(OR(COUNTIF(D8,"1.*"),COUNTIF(D8,"2.*"),COUNTIF(D8,"3.*"),COUNTIF(D8,"7.*")),K25*I24,""))
B26: 135 | C26: =A26*B26 -> 0
C27: =A27*B27 -> 0 | D27: =IF(OR(COUNTIF(D8,"1.*"),COUNTIF(D8,"2.*"),COUNTIF(D8,"3.*"),COUNTIF(D8,"7.*")),"Member Benefit Deferred at Age 65","") | H27: =IF(OR(COUNTIF(D8,"1.*"),COUNTIF(D8,"2.*"),COUNTIF(D8,"3.*"),COUNTIF(D8,"7.*")),SUM(H11,H14,H17),"") | I27: =IF(COUNTIF(C7,""),"",IF(OR(COUNTIF(D8,"2.*"),COUNTIF(D8,"7.*")),"Pension Benefit Deferred at Age 65 H&W Options",IF(COUNTIF(D8,"4.*"),"Regular at 62 & Disability H&W Combined Pension Options",IF(COUNTIF(D8,"8.*"),"Service Pre-Age 55 & Disability H&W Combined Pension Options","")))) -> Service Pre-Age 55 & Disability H&W Combined Pension Options
C28: =A28*B28 -> 0 | D28: =IF(OR(COUNTIF(D8,"1.*"),COUNTIF(D8,"2.*"),COUNTIF(D8,"3.*"),COUNTIF(D8,"7.*")),"Member 13th Check","") | H28: =IF(OR(COUNTIF(D8,"1.*"),COUNTIF(D8,"2.*"),COUNTIF(D8,"3.*"),COUNTIF(D8,"7.*")),SUM(H11,H14,H17),"") | I28: =IF(COUNTIF(C7,""),"",IF(OR(COUNTIF(D8,"2.*"),COUNTIF(D8,"7.*"),COUNTIF(D8,"8.*")),"Option","")) -> Option | J28: =IF(COUNTIF(C7,""),"",IF(OR(COUNTIF(D8,"2.*"),COUNTIF(D8,"7.*"),COUNTIF(D8,"8.*")),"Factor","")) -> Factor | K28: =IF(COUNTIF(C7,""),"",IF(OR(COUNTIF(D8,"2.*"),COUNTIF(D8,"7.*"),COUNTIF(D8,"8.*")),"Member Benefit","")) -> Member Benefit | L28: =IF(COUNTIF(C7,""),"",IF(OR(COUNTIF(D8,"2.*"),COUNTIF(D8,"7.*"),COUNTIF(D8,"8.*")),"Spouse Benefit","")) -> Spouse Benefit
C29: =A29*B29 -> 0 | I29: =IF(COUNTIF(C7,""),"",IF(OR(COUNTIF(D8,"2.*"),COUNTIF(D8,"7.*"),COUNTIF(D8,"8.*")),"50%","")) -> 50% | J29: =IF(COUNTIF(C7,""),"",IF(OR(COUNTIF(D8,"2.*"),COUNTIF(D8,"7.*")),IF(COUNTIF(K6,"*Younger*"),100%-8%-(J6*0.4%),IF(100%-8%+(J6*0.4%)>100%,100%,100%-8%+(J6*0.4%))),"")) | K29: =IF(COUNTIF(C7,""),"",IF(OR(COUNTIF(D8,"2.*"),COUNTIF(D8,"7.*")),((H11+H14+H17)*J29),"")) | L29: =IF(COUNTIF(C7,""),"",IF(OR(COUNTIF(D8,"2.*"),COUNTIF(D8,"7.*")),K29*I29,""))
A30: =SUM(A24:A29) -> 0 | B30: Subtotal | C30: =SUM(C24:C29) -> 0 | I30: =IF(COUNTIF(C7,""),"",IF(OR(COUNTIF(D8,"2.*"),COUNTIF(D8,"7.*"),COUNTIF(D8,"8.*")),"13th Check","")) -> 13th Check | J30: =IF(COUNTIF(C7,""),"",IF(OR(COUNTIF(D8,"2.*"),COUNTIF(D8,"7.*")),IF(COUNTIF(K6,"*Younger*"),100%-8%-(J6*0.4%),IF(100%-8%+(J6*0.4%)>100%,100%,100%-8%+(J6*0.4%))),"")) | K30: =IF(COUNTIF(C7,""),"",IF(OR(COUNTIF(D8,"2.*"),COUNTIF(D8,"7.*")),((H11+H14+H17)*J30),"")) | L30: =IF(COUNTIF(C7,""),"",IF(OR(COUNTIF(D8,"2.*"),COUNTIF(D8,"7.*")),K30*I29,""))
A31: =SUM(A18,A22,A30) -> 7.33 | B31: Total | C31: =SUM(C18,C22,C30) -> 876 | I31: =IF(COUNTIF(C7,""),"",IF(OR(COUNTIF(D8,"2.*"),COUNTIF(D8,"7.*"),COUNTIF(D8,"8.*")),"75%","")) -> 75% | J31: =IF(COUNTIF(C7,""),"",IF(OR(COUNTIF(D8,"2.*"),COUNTIF(D8,"7.*")),IF(COUNTIF(K6,"*Younger*"),100%-12%-(J6*0.4%),IF(100%-12%+(J6*0.4%)>100%,100%,100%-12%+(J6*0.4%))),"")) | K31: =IF(COUNTIF(C7,""),"",IF(OR(COUNTIF(D8,"2.*"),COUNTIF(D8,"7.*")),((H11+H14+H17)*J31),"")) | L31: =IF(COUNTIF(C7,""),"",IF(OR(COUNTIF(D8,"2.*"),COUNTIF(D8,"7.*")),K31*I31,""))
I32: =IF(COUNTIF(C7,""),"",IF(OR(COUNTIF(D8,"2.*"),COUNTIF(D8,"7.*"),COUNTIF(D8,"8.*")),"13th Check","")) -> 13th Check | J32: =IF(COUNTIF(C7,""),"",IF(OR(COUNTIF(D8,"2.*"),COUNTIF(D8,"7.*")),IF(COUNTIF(K6,"*Younger*"),100%-12%-(J6*0.4%),IF(100%-12%+(J6*0.4%)>100%,100%,100%-12%+(J6*0.4%))),"")) | K32: =IF(COUNTIF(C7,""),"",IF(OR(COUNTIF(D8,"2.*"),COUNTIF(D8,"7.*")),((H11+H14+H17)*J32),"")) | L32: =IF(COUNTIF(C7,""),"",IF(OR(COUNTIF(D8,"2.*"),COUNTIF(D8,"7.*")),K32*I31,""))
I33: =IF(COUNTIF(C7,""),"",IF(OR(COUNTIF(D8,"2.*"),COUNTIF(D8,"7.*"),COUNTIF(D8,"8.*")),"100%","")) -> 100% | J33: =IF(COUNTIF(C7,""),"",IF(OR(COUNTIF(D8,"2.*"),COUNTIF(D8,"7.*")),IF(COUNTIF(K6,"*Younger*"),100%-15%-(J6*0.5%),IF(100%-15%+(J6*0.5%)>100%,100%,100%-15%+(J6*0.5%))),"")) | K33: =IF(COUNTIF(C7,""),"",IF(OR(COUNTIF(D8,"2.*"),COUNTIF(D8,"7.*")),((H11+H14+H17)*J33),"")) | L33: =IF(COUNTIF(C7,""),"",IF(OR(COUNTIF(D8,"2.*"),COUNTIF(D8,"7.*")),K33*I33,""))
A34: Processed By: | B34: Alex Miles | E34: Checked By: | F34: Alex Miles | I34: =IF(COUNTIF(C7,""),"",IF(OR(COUNTIF(D8,"2.*"),COUNTIF(D8,"7.*"),COUNTIF(D8,"8.*")),"13th Check","")) -> 13th Check | J34: =IF(COUNTIF(C7,""),"",IF(OR(COUNTIF(D8,"2.*"),COUNTIF(D8,"7.*")),IF(COUNTIF(K6,"*Younger*"),100%-15%-(J6*0.5%),IF(100%-15%+(J6*0.5%)>100%,100%,100%-15%+(J6*0.5%))),"")) | K34: =IF(COUNTIF(C7,""),"",IF(OR(COUNTIF(D8,"2.*"),COUNTIF(D8,"7.*")),((H11+H14+H17)*J34),"")) | L34: =IF(COUNTIF(C7,""),"",IF(OR(COUNTIF(D8,"2.*"),COUNTIF(D8,"7.*")),K34*I33,""))
A36: Date: | B36: =TODAY() -> 46164 | E36: Date: | F36: =TODAY() -> 46164

Sheet Delayed
A1: California Ironworkers Field Pension Trust Pension Calculation | M1: Delayed Retirement Age 65 Pension Credit Separater
A2: Member Name: | C2: Richard E Hoitinga | H2: Member ID: | I2: 451973X00
A3: Member Date of Birth: | C3: 32593
A4: Member Age at Retirement: | C4: =DATEDIF(C3,C5,"y")&"/"&(DATEDIF(C3,C5, "m") - (DATEDIF(C3,C5, "y") * 12)) -> 65/0
A5: Member Retirement Date: | C5: 56340
A6: Spouse Name: | C6: Brooklyn A Hoitinga | G6: =IF(COUNTIF(C7,""),"","Spouse Age Difference from Member:") -> Spouse Age Difference from Member: | J6: =IF(C7=0,"",IF(AND(C3-C7<0,(DATEDIF(C3,C5,"m")-(DATEDIF(C3,C5,"y")*12))-(DATEDIF(C7,C5,"m")-(DATEDIF(C7,C5,"y")*12))=0),DATEDIF(C3,C5,"y")-DATEDIF(C7,C5,"y"),IF(AND(C3-C7>0,(DATEDIF(C7,C5,"m")-(DATEDIF(C7,C5,"y")*12))-(DATEDIF(C3,C5,"m")-(DATEDIF(C3,C5,"y")*12))=0),DATEDIF(C7,C5,"y")-DATEDIF(C3,C5,"y"),IF(C3-C7<0,ROUNDDOWN(YEARFRAC(C3,C7),0),IF(C3-C7>0,ROUNDDOWN(YEARFRAC(C7,C3),0),0))))) -> 2 | K6: =IF(C7=0,"",IF(J6=0,"No Difference.",IF(C3-C7<0,"Year(s) Younger.", IF(C3-C7>0, "Year(s) Older.","No Difference.")))) -> Year(s) Younger.
A7: Spouse Date of Birth: | C7: 33410
A8: =IF(COUNTIF(C7,""),"","Spouse Age at Retirement:") -> Spouse Age at Retirement: | C8: =IF(COUNTIF(C7,""),"",DATEDIF(C7,C5,"y")&"/"&(DATEDIF(C7,C5,"m")-(DATEDIF(C7,C5,"y")*12))) -> 62/9
A9: Credits Earned Prior to 09/01/2011 | D9: Delayed Pension Benefit Calculation | I9: =IF(COUNTIF(C7,""),"","Delayed 1 H&W Pension Options") -> Delayed 1 H&W Pension Options | M9: Plan Year | N9: =IF(MONTH(H18)>5,YEAR(H18)+1,YEAR(H18)) -> 2054
A10: CA Credits | B10: Rate | C10: Value | D10: Total Pension Credits | H10: =SUM(A11:A17,A20:A21,A24:A29,A33:A38) -> 44.38 | I10: =IF(COUNTIF(C7,""),"","Option") -> Option | J10: =IF(COUNTIF(C7,""),"","Factor") -> Factor | K10: =IF(COUNTIF(C7,""),"","Member Benefit") -> Member Benefit | L10: =IF(COUNTIF(C7,""),"","Spouse Benefit") -> Spouse Benefit | M10: Month | N10: Hours | O10: Pension Credits
C11: =A11*B11 -> 0 | D11: Member Benefit Prior to 09/01/2011 | G11: =SUM(A11:A17) -> 26.96 | H11: =SUM(C11:C17) -> 3208.79 | I11: =IF(COUNTIF(C7,""),"","50%") -> 50% | J11: =IF(COUNTIF(C7,""),"",IF(COUNTIF(K6,"*Younger*"),100%-8%-(J6*0.4%),IF(100%-8%+(J6*0.4%)>100%,100%,100%-8%+(J6*0.4%)))) -> 0.912 | K11: =IF(COUNTIF(C7,""),"",(C18+C22+C30+C39)*J11) -> 5031.6773 | L11: =IF(COUNTIF(C7,""),"",K11*I11) -> 2515.8386 | M11: =IF(AND(MONTH(H18)=5,DAY(H18)>1),"Member turned 65 in May",IF(AND(MONTH(H18)=5,DAY(H18)=1),"Member turned 65 at the start of May","May")) -> May | N11: 125 | O11: =IF(N9=2015,ROUND(ROUNDDOWN((SUM(N11))/117,0)/12,2),"")
C12: =A12*B12 -> 0 | I12: =IF(COUNTIF(C7,""),"","13th Check") -> 13th Check | J12: =IF(COUNTIF(C7,""),"",IF(COUNTIF(K6,"*Younger*"),100%-8%-(J6*0.4%),IF(100%-8%+(J6*0.4%)>100%,100%,100%-8%+(J6*0.4%)))) -> 0.912 | K12: =IF(COUNTIF(C7,""),"",(C18+C22+C30+C39)*J12) -> 5031.6773 | L12: =IF(COUNTIF(C7,""),"",K12*I11) -> 2515.8386 | M12: =IF(AND(MONTH(H18)=4,DAY(H18)>1),"Member turned 65 in April",IF(AND(MONTH(H18)=4,DAY(H18)=1),"Member turned 65 at the start April","April")) -> April | N12: 125 | O12: =IF(N9=2015,ROUND(ROUNDDOWN((SUM(N11:N12))/117,0)/12,2),"")
C13: =A13*B13 -> 0 | D13: Member Benefit from 09/01/2011 to 09/30/2014 | G13: =SUM(A20:A21) -> 4.33 | H13: =SUM(C20:C21) -> 541.25 | I13: =IF(COUNTIF(C7,""),"","75%") -> 75% | J13: =IF(COUNTIF(C7,""),"",IF(COUNTIF(K6,"*Younger*"),100%-12%-(J6*0.4%),IF(100%-12%+(J6*0.4%)>100%,100%,100%-12%+(J6*0.4%)))) -> 0.872 | K13: =IF(COUNTIF(C7,""),"",(C18+C22+C30+C39)*J13) -> 4810.9897 | L13: =IF(COUNTIF(C7,""),"",K13*I13) -> 3608.2423 | M13: =IF(AND(MONTH(H18)=3,DAY(H18)>1),"Member turned 65 in March",IF(AND(MONTH(H18)=3,DAY(H18)=1),"Member turned 65 at the start of March","March")) -> Member turned 65 in March | N13: 125 | O13: =IF(N9=2015,ROUND(ROUNDDOWN((SUM(N11:N13))/117,0)/12,2),"")
B14: 50 | C14: =A14*B14 -> 0 | I14: =IF(COUNTIF(C7,""),"","13th Check") -> 13th Check | J14: =IF(COUNTIF(C7,""),"",IF(COUNTIF(K6,"*Younger*"),100%-12%-(J6*0.4%),IF(100%-12%+(J6*0.4%)>100%,100%,100%-12%+(J6*0.4%)))) -> 0.872 | K14: =IF(COUNTIF(C7,""),"",(C18+C22+C30+C39)*J14) -> 4810.9897 | L14: =IF(COUNTIF(C7,""),"",K14*I13) -> 3608.2423 | M14: =IF(AND(MONTH(H18)=2,DAY(H18)>1),"Member turned 65 in February",IF(AND(MONTH(H18)=2,DAY(H18)=1),"Member turned 65 at the start February","February")) -> February | N14: 125 | O14: =IF(N9=2015,ROUND(ROUNDDOWN((SUM(N11:N14))/117,0)/12,2),"")
A15: 23.03 | B15: 118 | C15: =A15*B15 -> 2717.54 | D15: Member Benefit on or After 10/01/2014 | G15: =SUM(A24:A29,A33:A38) -> 13.09 | H15: =SUM(C24:C29,C33:C38) -> 1767.15 | I15: =IF(COUNTIF(C7,""),"","100%") -> 100% | J15: =IF(COUNTIF(C7,""),"",IF(COUNTIF(K6,"*Younger*"),100%-15%-(J6*0.5%),IF(100%-15%+(J6*0.5%)>100%,100%,100%-15%+(J6*0.5%)))) -> 0.84 | K15: =IF(COUNTIF(C7,""),"",(C18+C22+C30+C39)*J15) -> 4634.4396 | L15: =IF(COUNTIF(C7,""),"",K15*I15) -> 4634.4396 | M15: =IF(AND(MONTH(H18)=1,DAY(H18)>1),"Member turned 65 in January",IF(AND(MONTH(H18)=1,DAY(H18)=1),"Member turned 65 at the start of January","January")) -> January | N15: 125 | O15: =IF(N9=2015,(ROUND(ROUNDDOWN(SUM(N15)/125,0)/12,2)+(ROUND(ROUNDDOWN(SUM(N11:N14)/117,0)/12,2))),"")
B16: 105 | C16: =A16*B16 -> 0 | D16: Member Delayed Calculation 1 Monthly Amount | H16: =SUM(C11:C17,C20:C21,C24:C29,C33:C38) -> 5517.19 | I16: =IF(COUNTIF(C7,""),"","13th Check") -> 13th Check | J16: =IF(COUNTIF(C7,""),"",IF(COUNTIF(K6,"*Younger*"),100%-15%-(J6*0.5%),IF(100%-15%+(J6*0.5%)>100%,100%,100%-15%+(J6*0.5%)))) -> 0.84 | K16: =IF(COUNTIF(C7,""),"",(C18+C22+C30+C39)*J16) -> 4634.4396 | L16: =IF(COUNTIF(C7,""),"",K16*I15) -> 4634.4396 | M16: =IF(AND(MONTH(H18)=12,DAY(H18)>1),"Member turned 65 in December",IF(AND(MONTH(H18)=12,DAY(H18)=1),"Member turned 65 at the start of December","December")) -> December | N16: 125 | O16: =IF(N9=2015,(ROUND(ROUNDDOWN(SUM(N15:N16)/125,0)/12,2)+(ROUND(ROUNDDOWN(SUM(N11:N14)/117,0)/12,2))),"")
A17: 3.93 | B17: 125 | C17: =A17*B17 -> 491.25 | D17: Member Calculation 1 13th Check Amount | H17: =SUM(C11:C17,C20:C21,C24:C29,C33:C38) -> 5517.19 | M17: =IF(AND(MONTH(H18)=11,DAY(H18)>1),"Member turned 65 in November",IF(AND(MONTH(H18)=11,DAY(H18)=1),"Member turned 65 at the start of November","November")) -> November | N17: 125 | O17: =IF(N9=2015,(ROUND(ROUNDDOWN(SUM(N15:N17)/125,0)/12,2)+(ROUND(ROUNDDOWN(SUM(N11:N14)/117,0)/12,2))),"")
A18: =SUM(A11:A17) -> 26.96 | B18: Subtotal | C18: =SUM(C11:C17) -> 3208.79 | D18: Date member turned 65 | G18: =SUM(A11:A17,A20:A21,A24:A29) -> 43.05 | H18: =EDATE(C3, 65 * 12) -> 56334 | I18: =IF(COUNTIF(C7,""),"","Delayed 2 H&W Pension Options") -> Delayed 2 H&W Pension Options | M18: =IF(AND(MONTH(H18)=10,DAY(H18)>1),"Member turned 65 in October",IF(AND(MONTH(H18)=10,DAY(H18)=1),"Member turned 65 at the start of October","October")) -> October | N18: 125 | O18: =IF(N9=2015,(ROUND(ROUNDDOWN(SUM(N15:N18)/125,0)/12,2)+(ROUND(ROUNDDOWN(SUM(N11:N14)/117,0)/12,2))),"")
A19: Credits Earned On or After 09/01/2011 | D19: =IF(DATEDIF(C3,C5,"m")>=846,"Date member turned 70 1/2","") | H19: =IF(DATEDIF(C3,C5,"m")>=846,EDATE(C3,70*12+6),"") | I19: =IF(COUNTIF(C7,""),"","Option") -> Option | J19: =IF(COUNTIF(C7,""),"","Factor") -> Factor | K19: =IF(COUNTIF(C7,""),"","Member Benefit") -> Member Benefit | L19: =IF(COUNTIF(C7,""),"","Spouse Benefit") -> Spouse Benefit | M19: =IF(AND(MONTH(H18)=9,DAY(H18)>1),"Member turned 65 in September",IF(AND(MONTH(H18)=9,DAY(H18)=1),"Member turned 65 at the start of September","September")) -> September | N19: 125 | O19: =IF(N9=2015,(ROUND(ROUNDDOWN(SUM(N15:N19)/125,0)/12,2)+(ROUND(ROUNDDOWN(SUM(N11:N14)/117,0)/12,2))),"")
B20: 90 | C20: =A20*B20 -> 0 | D20: Pre-65 Monthly Pension Amount | H20: =SUM(C11:C17,C20:C21,C24:C29) -> 5337.64 | I20: =IF(COUNTIF(C7,""),"",50%) -> 0.5 | J20: =IF(COUNTIF(C7,""),"",IF(COUNTIF(K6,"*Younger*"),100%-8%-(J6*0.4%),IF(100%-8%+(J6*0.4%)>100%,100%,100%-8%+(J6*0.4%)))) -> 0.912 | K20: =IF(COUNTIF(C7,""),"",(((C18+C22+C30)*((H22*1%)+(H23*1.5%)))+(C18+C22+C30))*J20) -> 6717.7402 | L20: =IF(COUNTIF(C7,""),"",K20*I20) -> 3358.8701 | M20: =IF(AND(MONTH(H18)=8,DAY(H18)>1),"Member turned 65 in August",IF(AND(MONTH(H18)=8,DAY(H18)=1),"Member turned 65 at the start of August","August")) -> August | N20: 125 | O20: =IF(N9=2015,(ROUND(ROUNDDOWN(SUM(N15:N20)/125,0)/12,2)+(ROUND(ROUNDDOWN(SUM(N11:N14)/117,0)/12,2))),"")
A21: 4.33 | B21: 125 | C21: =A21*B21 -> 541.25 | D21: Pre-65 13th Check Amount | H21: =SUM(C11:C17,C20:C21,C24:C29) -> 5337.64 | I21: =IF(COUNTIF(C7,""),"","13th Check") -> 13th Check | J21: =IF(COUNTIF(C7,""),"",IF(COUNTIF(K6,"*Younger*"),100%-8%-(J6*0.4%),IF(100%-8%+(J6*0.4%)>100%,100%,100%-8%+(J6*0.4%)))) -> 0.912 | K21: =IF(COUNTIF(C7,""),"",(((C18+C22+C30)*((H22*1%)+(H23*1.5%)))+(C18+C22+C30))*J21) -> 6717.7402 | L21: =IF(COUNTIF(C7,""),"",K21*I20) -> 3358.8701 | M21: =IF(AND(MONTH(H18)=7,DAY(H18)>1),"Member turned 65 in July",IF(AND(MONTH(H18)=7,DAY(H18)=1),"Member turned 65 at the start of July","July")) -> July | N21: 125 | O21: =IF(N9=2015,(ROUND(ROUNDDOWN(SUM(N15:N21)/125,0)/12,2)+(ROUND(ROUNDDOWN(SUM(N11:N14)/117,0)/12,2))),"")
A22: =SUM(A20:A21) -> 4.33 | B22: Subtotal | C22: =SUM(C20:C21) -> 541.25 | D22: First 60 months with 40 hours or less (1.00%): | H22: 38 | I22: =IF(COUNTIF(C7,""),"","75%") -> 75% | J22: =IF(COUNTIF(C7,""),"",IF(COUNTIF(K6,"*Younger*"),100%-12%-(J6*0.4%),IF(100%-12%+(J6*0.4%)>100%,100%,100%-12%+(J6*0.4%)))) -> 0.872 | K22: =IF(COUNTIF(C7,""),"",(((C18+C22+C30)*((H22*1%)+(H23*1.5%)))+(C18+C22+C30))*J22) -> 6423.1025 | L22: =IF(COUNTIF(C7,""),"",K22*I22) -> 4817.3269 | M22: =IF(AND(MONTH(H18)=6,DAY(H18)>1),"Member turned 65 in June",IF(AND(MONTH(H18)=6,DAY(H18)=1),"Member turned 65 at the start of June","June")) -> June | N22: 125 | O22: =IF(N9=2015,(ROUND(ROUNDDOWN(SUM(N15:N22)/125,0)/12,2)+(ROUND(ROUNDDOWN(SUM(N11:N14)/117,0)/12,2))),"")
A23: Credits Earned On or After 10/01/2014 | D23: 61 + months with 40 hours or less (1.50%): | I23: =IF(COUNTIF(C7,""),"","13th Check") -> 13th Check | J23: =IF(COUNTIF(C7,""),"",IF(COUNTIF(K6,"*Younger*"),100%-12%-(J6*0.4%),IF(100%-12%+(J6*0.4%)>100%,100%,100%-12%+(J6*0.4%)))) -> 0.872 | K23: =IF(COUNTIF(C7,""),"",(((C18+C22+C30)*((H22*1%)+(H23*1.5%)))+(C18+C22+C30))*J23) -> 6423.1025 | L23: =IF(COUNTIF(C7,""),"",K23*I22) -> 4817.3269 | M23: ="Total hours and credits in PY "&IF(MONTH(H18)>5,YEAR(H18)+1,YEAR(H18)) -> Total hours and credits in PY 2054 | N23: =SUM(N11:N22) -> 1500 | O23: =IF(N9<2015,ROUND(ROUNDDOWN(N23/117,0)/12,2),IF(N9>2015,ROUND(ROUNDDOWN(N23/125,0)/12,2),(ROUNDDOWN(SUM(N11:N14/117,0)/12,2))+(ROUNDDOWN(SUM(N15:N22/125,0)/12,2)))) -> 1
B24: 105 | C24: =A24*B24 -> 0 | D24: Delayed Calc 2 Retirement Increase: | H24: =SUM(H22*1%)+(H23*1.5%) -> 0.38 | I24: =IF(COUNTIF(C7,""),"","100%") -> 100% | J24: =IF(COUNTIF(C7,""),"",IF(COUNTIF(K6,"*Younger*"),100%-15%-(J6*0.5%),IF(100%-15%+(J6*0.5%)>100%,100%,100%-15%+(J6*0.5%)))) -> 0.84 | K24: =IF(COUNTIF(C7,""),"",(((C18+C22+C30)*((H22*1%)+(H23*1.5%)))+(C18+C22+C30))*J24) -> 6187.3923 | L24: =IF(COUNTIF(C7,""),"",K24*I24) -> 6187.3923 | M24: Pre-65 hours total | N24: =IF(MONTH(H18)=6,IF(DAY(H18)=1,0,N22),IF(MONTH(H18)=7,IF(DAY(H18)=1,N22,SUM(N21:N22)),IF(MONTH(H18)=8,IF(DAY(H18)=1,SUM(N21:N22),SUM(N20:N22)),IF(MONTH(H18)=9,IF(DAY(H18)=1,SUM(N20:N22),SUM(N19:N22)),IF(MONTH(H18)=10,IF(DAY(H18)=1,SUM(N19:N22),SUM(N18:N22)),IF(MONTH(H18)=11,IF(DAY(H18)=1,SUM(N18:N22),SUM(N17:N22)),IF(MONTH(H18)=12,IF(DAY(H18)=1,SUM(N17:N22),SUM(N16:N22)),IF(MONTH(H18)=1,IF(DAY(H18)=1,SUM(N16:N22),SUM(N15:N22)),IF(MONTH(H18)=2,IF(DAY(H18)=1,SUM(N15:N22),SUM(N14:N22)),IF(MONTH(H18)=3,IF(DAY(H18)=1,SUM(N14:N22),SUM(N13:N22)),IF(MONTH(H18)=4,IF(DAY(H18)=1,SUM(N13:N22),SUM(N12:N22)),IF(MONTH(H18)=5,IF(DAY(H18)=1,SUM(N12:N22),SUM(N11:N22)))))))))))))) -> 1250 | O24: =IF(N9<2015,ROUND(ROUNDDOWN(N24/117,0)/12,2),IF(N9>2015,ROUND(ROUNDDOWN(N24/125,0)/12,2),ROUNDDOWN(SUM(N11:N14/117,0)/12,2)+ROUNDDOWN(SUM(N15:N22/125,0)/12,2))) -> 0.83
B25: 125 | C25: =A25*B25 -> 0 | D25: Delayed Benefit Increase | H25: =SUM(C18+C22+C30)*H24 -> 2028.3032 | I25: =IF(COUNTIF(C7,""),"","13th Check") -> 13th Check | J25: =IF(COUNTIF(C7,""),"",IF(COUNTIF(K6,"*Younger*"),100%-15%-(J6*0.5%),IF(100%-15%+(J6*0.5%)>100%,100%,100%-15%+(J6*0.5%)))) -> 0.84 | K25: =IF(COUNTIF(C7,""),"",(((C18+C22+C30)*((H22*1%)+(H23*1.5%)))+(C18+C22+C30))*J24) -> 6187.3923 | L25: =IF(COUNTIF(C7,""),"",K25*I24) -> 6187.3923 | M25: ="Credits earned Post-65 in PY "&IF(MONTH(H18)>5,YEAR(H18)+1,YEAR(H18)) -> Credits earned Post-65 in PY 2054 | O25: =O23-O24 -> 0.17
A26: 11.76 | B26: 135 | C26: =A26*B26 -> 1587.6 | D26: Delayed 13th Check Increase | H26: =SUM(C18+C22+C30)*H24 -> 2028.3032
C27: =A27*B27 -> 0 | D27: Delayed Calc 2 Member Benefit: | H27: =SUM(C18,C22,C30)*((H22*1%)+(H23*1.5%))+(C18+C22+C30) -> 7365.9432
C28: =A28*B28 -> 0 | D28: Delayed Calc 2 Member 13th Check: | H28: =SUM(C18,C22,C30)*((H22*1%)+(H23*1.5%))+(C18+C22+C30) -> 7365.9432
C29: =A29*B29 -> 0
A30: =SUM(A24:A29) -> 11.76 | B30: Subtotal | C30: =SUM(C24:C29) -> 1587.6 | D30: Delayed Calculation 1 Benefit Amount: | H30: =H16 -> 5517.19
A31: =SUM(A18,A22,A30) -> 43.05 | B31: Pre-65 Total | C31: =SUM(C18,C22,C30) -> 5337.64 | D31: Delayed Calculation 2 Benefit Amount: | H31: =H27 -> 7365.9432
A32: Credits Earned After Age 65 | D32: Greater of Calculation 1 and 2: | G32: =IF(H30=H31,"No Difference",IF(H30<H31,"Calculation 2","Calculation 1")) -> Calculation 2 | H32: =IF(H30=H31,H30,IF(H30<H31,H31,H30)) -> 7365.9432
B33: 105 | C33: =(A33*B33) -> 0
B34: 125 | C34: =(A34*B34) -> 0
A35: 1.33 | B35: 135 | C35: =(A35*B35) -> 179.55
C36: =(A36*B36) -> 0
C37: =(A37*B37) -> 0 | D37: Processed By: | E37: Alex Miles | H37: Checked By:
C38: =(A38*B38) -> 0
A39: =SUM(A33:A38) -> 1.33 | B39: Subtotal | C39: =SUM(C33:C38) -> 179.55 | D39: Date: | E39: =TODAY() -> 46164 | H39: Date:
A40: =SUM(A18,A22,A30,A39) -> 44.38 | B40: Total | C40: =SUM(C18,C22,C30,C39) -> 5517.19

Sheet Pro-Rata Worksheet
D1: PRO RATA CALCULATION WORKSHEET
A2: Participant Name: | C2: Julian A. Jove | H2: ID: | I2: 200180x00
I3: Combined PC | J3: Combined PC
A4: Plan Year | B4: CA | D4: 720 | I4: (1PC max / $) | J4: (combined/elig/%)
A5: Totals | B5: =SUM(B6:B69) -> 10.65 | C5: =SUM(C6:C69) -> 1 | D5: =SUM(D6:D69) -> 0 | E5: =SUM(E6:E69) -> 0 | F5: =SUM(F6:F69) -> 0 | G5: =SUM(G6:G69) -> 0 | H5: =SUM(H6:H69) -> 0 | I5: =SUM(I6:I69) -> 11.65 | J5: =SUM(J6:J69) -> 11.65
A6: 2035 | I6: =IF(AND(SUM(B6:H6)>=1,B6<=1),1,IF((B6>1),B6,SUM(B6:H6))) -> 0 | J6: =SUM(B6:H6) -> 0
A7: 2034 | I7: =IF(AND(SUM(B7:H7)>=1,B7<=1),1,IF((B7>1),B7,SUM(B7:H7))) -> 0 | J7: =SUM(B7:H7) -> 0
A8: 2033 | I8: =IF(AND(SUM(B8:H8)>=1,B8<=1),1,IF((B8>1),B8,SUM(B8:H8))) -> 0 | J8: =SUM(B8:H8) -> 0
A9: 2032 | I9: =IF(AND(SUM(B9:H9)>=1,B9<=1),1,IF((B9>1),B9,SUM(B9:H9))) -> 0 | J9: =SUM(B9:H9) -> 0
A10: 2031 | I10: =IF(AND(SUM(B10:H10)>=1,B10<=1),1,IF((B10>1),B10,SUM(B10:H10))) -> 0 | J10: =SUM(B10:H10) -> 0
A11: 2030 | I11: =IF(AND(SUM(B11:H11)>=1,B11<=1),1,IF((B11>1),B11,SUM(B11:H11))) -> 0 | J11: =SUM(B11:H11) -> 0
A12: 2029 | I12: =IF(AND(SUM(B12:H12)>=1,B12<=1),1,IF((B12>1),B12,SUM(B12:H12))) -> 0 | J12: =SUM(B12:H12) -> 0
A13: 2028 | I13: =IF(AND(SUM(B13:H13)>=1,B13<=1),1,IF((B13>1),B13,SUM(B13:H13))) -> 0 | J13: =SUM(B13:H13) -> 0
A14: 2027 | I14: =IF(AND(SUM(B14:H14)>=1,B14<=1),1,IF((B14>1),B14,SUM(B14:H14))) -> 0 | J14: =SUM(B14:H14) -> 0
A15: 2026 | I15: =IF(AND(SUM(B15:H15)>=1,B15<=1),1,IF((B15>1),B15,SUM(B15:H15))) -> 0 | J15: =SUM(B15:H15) -> 0
A16: 2025 | B16: 0.67 | I16: =IF(AND(SUM(B16:H16)>=1,B16<=1),1,IF((B16>1),B16,SUM(B16:H16))) -> 0.67 | J16: =SUM(B16:H16) -> 0.67
A17: 2024 | B17: 0.33 | I17: =IF(AND(SUM(B17:H17)>=1,B17<=1),1,IF((B17>1),B17,SUM(B17:H17))) -> 0.33 | J17: =SUM(B17:H17) -> 0.33
A18: 2023 | B18: 0.75 | I18: =IF(AND(SUM(B18:H18)>=1,B18<=1),1,IF((B18>1),B18,SUM(B18:H18))) -> 0.75 | J18: =SUM(B18:H18) -> 0.75
A19: 2022 | I19: =IF(AND(SUM(B19:H19)>=1,B19<=1),1,IF((B19>1),B19,SUM(B19:H19))) -> 0 | J19: =SUM(B19:H19) -> 0
A20: 2021 | I20: =IF(AND(SUM(B20:H20)>=1,B20<=1),1,IF((B20>1),B20,SUM(B20:H20))) -> 0 | J20: =SUM(B20:H20) -> 0
A21: 2020 | B21: 0.25 | I21: =IF(AND(SUM(B21:H21)>=1,B21<=1),1,IF((B21>1),B21,SUM(B21:H21))) -> 0.25 | J21: =SUM(B21:H21) -> 0.25
A22: 2019 | B22: 0.42 | I22: =IF(AND(SUM(B22:H22)>=1,B22<=1),1,IF((B22>1),B22,SUM(B22:H22))) -> 0.42 | J22: =SUM(B22:H22) -> 0.42
A23: 2018 | B23: 0.42 | I23: =IF(AND(SUM(B23:H23)>=1,B23<=1),1,IF((B23>1),B23,SUM(B23:H23))) -> 0.42 | J23: =SUM(B23:H23) -> 0.42
A24: 2017 | B24: 0.33 | I24: =IF(AND(SUM(B24:H24)>=1,B24<=1),1,IF((B24>1),B24,SUM(B24:H24))) -> 0.33 | J24: =SUM(B24:H24) -> 0.33
A25: 2016 | B25: 0.33 | I25: =IF(AND(SUM(B25:H25)>=1,B25<=1),1,IF((B25>1),B25,SUM(B25:H25))) -> 0.33 | J25: =SUM(B25:H25) -> 0.33
A26: 2015b | I26: {=IF(SUM(B26:B27)>=1,B26,IF(SUM(B26:H26+B27:H27)>=1,SUM(B26:H26/SUM(B26:H26+B27:H27)),SUM(B26:H26)))} -> 0 | J26: =SUM(B26:H26) -> 0
A27: 2015a | I27: {=IF(SUM(B26:B27)>=1,B27,IF(SUM(B26:H26+B27:H27)>=1,SUM(B27:H27/SUM(B26:H26+B27:H27)),SUM(B27:H27)))} -> 0 | J27: =SUM(B27:H27) -> 0
A28: 2014 | C28: 1 | I28: =IF(AND(SUM(B28:H28)>=1,B28<=1),1,IF((B28>1),B28,SUM(B28:H28))) -> 1 | J28: =SUM(B28:H28) -> 1
A29: 2013 | I29: =IF(AND(SUM(B29:H29)>=1,B29<=1),1,IF((B29>1),B29,SUM(B29:H29))) -> 0 | J29: =SUM(B29:H29) -> 0
A30: 2012b | B30: 0.08 | I30: {=IF(SUM(B30:B31)>=1,B30,IF(SUM(B30:H30+B31:H31)>=1,SUM(B30:H30/SUM(B30:H30+B31:H31)),SUM(B30:H30)))} -> 0.08 | J30: =SUM(B30:H30) -> 0.08
A31: 2012a | B31: 0.33 | I31: {=IF(SUM(B30:B31)>=1,B31,IF(SUM(B30:H30+B31:H31)>=1,SUM(B31:H31/SUM(B30:H30+B31:H31)),SUM(B31:H31)))} -> 0.33 | J31: =SUM(B31:H31) -> 0.33
A32: 2011 | B32: 0.58 | I32: =IF(AND(SUM(B32:H32)>=1,B32<=1),1,IF((B32>1),B32,SUM(B32:H32))) -> 0.58 | J32: =SUM(B32:H32) -> 0.58
A33: 2010 | B33: 0.83 | I33: =IF(AND(SUM(B33:H33)>=1,B33<=1),1,IF((B33>1),B33,SUM(B33:H33))) -> 0.83 | J33: =SUM(B33:H33) -> 0.83
A34: 2009 | I34: =IF(AND(SUM(B34:H34)>=1,B34<=1),1,IF((B34>1),B34,SUM(B34:H34))) -> 0 | J34: =SUM(B34:H34) -> 0
A35: 2008 | B35: 1.08 | I35: =IF(AND(SUM(B35:H35)>=1,B35<=1),1,IF((B35>1),B35,SUM(B35:H35))) -> 1.08 | J35: =SUM(B35:H35) -> 1.08
A36: 2007 | B36: 1 | I36: =IF(AND(SUM(B36:H36)>=1,B36<=1),1,IF((B36>1),B36,SUM(B36:H36))) -> 1 | J36: =SUM(B36:H36) -> 1
A37: 2006 | B37: 0.67 | I37: =IF(AND(SUM(B37:H37)>=1,B37<=1),1,IF((B37>1),B37,SUM(B37:H37))) -> 0.67 | J37: =SUM(B37:H37) -> 0.67
A38: 2005 | B38: 1 | I38: =IF(AND(SUM(B38:H38)>=1,B38<=1),1,IF((B38>1),B38,SUM(B38:H38))) -> 1 | J38: =SUM(B38:H38) -> 1
A39: 2004 | B39: 1.08 | I39: =IF(AND(SUM(B39:H39)>=1,B39<=1),1,IF((B39>1),B39,SUM(B39:H39))) -> 1.08 | J39: =SUM(B39:H39) -> 1.08
A40: 2003 | B40: 0.5 | I40: =IF(AND(SUM(B40:H40)>=1,B40<=1),1,IF((B40>1),B40,SUM(B40:H40))) -> 0.5 | J40: =SUM(B40:H40) -> 0.5
...

Sheet QDRO Pension Calculator
A1: California Ironworkers Field Pension Trust Pension Calculation | J1: California Ironworkers Field Pension Trust Pension Calculation
A2: Member Name: | C2: Martin E. Johnson | E2: Member ID: | F2: 336945X64 | K2: Processed By: | M2: Alex Miles
A3: Member Date of Birth: | C3: 23303
A4: Member Age at Retirement: | C4: =DATEDIF(C3,C5,"y")&"/"&(DATEDIF(C3,C5, "m") - (DATEDIF(C3,C5, "y") * 12)) -> 65/0 | K4: Date: | M4: =TODAY() -> 46164
A5: Member Retirement Date: | C5: 47058
A6: Spouse Name: | K6: Checked By:
A7: Spouse Date of Birth:
A8: Spouse Age at Retirement: | C8: =IF(COUNTIF(C7,""),"",DATEDIF(C7,C5,"y")&"/"&(DATEDIF(C7,C5,"m")-(DATEDIF(C7,C5,"y")*12))) | E8: =IF(C7=0,"","Spouse Age Difference from Member:") | H8: =IF(C7=0,"",IF(AND(C3-C7<0,(DATEDIF(C3,C5,"m")-(DATEDIF(C3,C5,"y")*12))-(DATEDIF(C7,C5,"m")-(DATEDIF(C7,C5,"y")*12))=0),DATEDIF(C3,C5,"y")-DATEDIF(C7,C5,"y"),IF(AND(C3-C7>0,(DATEDIF(C7,C5,"m")-(DATEDIF(C7,C5,"y")*12))-(DATEDIF(C3,C5,"m")-(DATEDIF(C3,C5,"y")*12))=0),DATEDIF(C7,C5,"y")-DATEDIF(C3,C5,"y"),IF(C3-C7<0,ROUNDDOWN(YEARFRAC(C3,C7),0),IF(C3-C7>0,ROUNDDOWN(YEARFRAC(C7,C3),0),0))))) | I8: =IF(C7=0,"",IF(H8=0,"No Difference.",IF(C3-C7<0,"Year(s) Younger.", IF(C3-C7>0, "Year(s) Older.","No Difference.")))) | K8: Date:
A9: Credits Earned Prior to 09/01/2011 | J9: 5. Regular at 65 | O9: =IF(COUNTIF(C7,""),"",IF(COUNTIF(J9,"1.*"),"Early Retirement H&W Pension Options",IF(COUNTIF(J9,"2.*"),"Regular at 62 H&W Pension Options",IF(COUNTIF(J9,"3.*"),"Regular at 62 & Early H&W Pension Options",IF(COUNTIF(J9,"4.*"),"Regular at 62 & Disability H&W Pension Options",IF(COUNTIF(J9,"5.*"),"Regular at 65 H&W Pension Options",IF(COUNTIF(J9,"6.*"),"Disability H&W Pension Options",IF(COUNTIF(J9,"7.*"),"Service Pre-Age 55 & Early H&W Pension Options",IF(COUNTIF(J9,"8.*"),"Service Pre-Age 55 & Disability H&W Pension Options",IF(COUNTIF(J9,"9.*"),"Service H&W Pension Options",L44&" Delayed H&W Options"))))))))))
A10: Member Credits | B10: =IF(COUNTIF(A34,"1.*"),"During AP 1 Marriage","") | C10: =IF(COUNTIF(A34,"1.*"),"AP 1 Credits","") | D10: =IF(COUNTIF(E34,"1.*"),"During AP 2 Marriage","") | E10: =IF(COUNTIF(E34,"1.*"),"AP 2 Credits","") | F10: Rate | G10: Member Value | H10: =IF(COUNTIF(A34,"1.*"),"AP 1 Value","") | I10: =IF(COUNTIF(E34,"1.*"),"AP 2 Value","") | J10: Benefit Calculation | O10: =IF(COUNTIF(C7,""),"","Option") | P10: =IF(COUNTIF(C7,""),"","Factor") | Q10: =IF(COUNTIF(C7,""),"","Member Benefit") | R10: =IF(COUNTIF(C7,""),"","Spouse Benefit")
C11: =IF(COUNTIF(A34,"1.*"),B11*D39,"") | E11: =IF(COUNTIF(E34,"1.*"),D11*H39,"") | G11: =IF(AND(COUNTIF(A34,"1.*"),COUNTIF(E34,"1.*")),SUM(A11*F11)-((C11*F11)+(E11*F11)),IF(COUNTIF(A34,"1.*"),SUM(A11*F11)-(C11*F11),IF(COUNTIF(E34,"1.*"),SUM(A11*F11)-(E11*F11),A11*F11))) -> 0 | H11: =IF(COUNTIF(A34,"1.*"),SUM(C11*F11),"") | I11: =IF(COUNTIF(E34,"1.*"),SUM(E11*F11),"") | J11: Full Benefit Prior to 09/01/2011: | M11: =SUM(A11:A16) -> 15.51 | N11: =SUM(A11*F11,A12*F12,A13*F13,A14*F14,A15*F15,A16*F16) -> 1848.87 | O11: =IF(COUNTIF(C7,""),"","50%") | P11: =IF(COUNTIF(C7,""),"",IF(COUNTIF(J9,"4.*"),IF(COUNTIF(I8,"*Younger*"),100%-8%-(H8*0.4%),IF(100%-8%+(H8*0.4%)>100%,100%,100%-8%+(H8*0.4%)))*100&"% / "&IF(COUNTIF(I8,"*Younger*"),100%-18%-(H8*0.4%),IF(100%-18%+(H8*0.4%)>100%,100%,100%-18%+(H8*0.4%)))*100&"%",IF(COUNTIF(J9,"6.*"),IF(COUNTIF(I8,"*Younger*"),100%-18%-(H8*0.4%),IF(100%-18%+(H8*0.4%)>100%,100%,100%-18%+(H8*0.4%))),IF(COUNTIF(J9,"8.*"),IF(COUNTIF(I8,"*Younger*"),100%-8%-(H8*0.4%),IF(100%-8%+(H8*0.4%)>100%,100%,100%-8%+(H8*0.4%)))*100&"% / "&IF(COUNTIF(I8,"*Younger*"),100%-18%-(H8*0.4%),IF(100%-18%+(H8*0.4%)>100%,100%,100%-18%+(H8*0.4%)))*100&"%",IF(COUNTIF(I8,"*Younger*"),100%-8%-(H8*0.4%),IF(100%-8%+(H8*0.4%)>100%,100%,100%-8%+(H8*0.4%))))))) | Q11: =IF(COUNTIF(C7,""),"",IF(COUNTIF(J9,"1.*"),(N40)*P11,IF(COUNTIF(J9,"2.*"),(N40)*P11,IF(COUNTIF(J9,"3.*"),(N40)*P11,IF(COUNTIF(J9,"5.*"),(N40)*P11,IF(COUNTIF(J9,"6.*"),(N40)*P11,IF(COUNTIF(J9,"7.*"),(N40)*P11,IF(COUNTIF(J9,"8.*"),(N11+N12)*IF(COUNTIF(I8,"*Younger*"),100%-8%-(H8*0.4%),IF(100%-8%+(H8*0.4%)>100%,100%,100%-8%+(H8*0.4%)))+(N13*IF(COUNTIF(I8,"*Younger*"),100%-18%-(H8*0.4%),IF(100%-18%+(H8*0.4%)>100%,100%,100%-18%+(H8*0.4%)))),IF(COUNTIF(J9,"4.*"),N11*IF(COUNTIF(I8,"*Younger*"),100%-8%-(H8*0.4%),IF(100%-8%+(H8*0.4%)>100%,100%,100%-8%+(H8*0.4%)))+(N12+N13)*IF(COUNTIF(I8,"*Younger*"),100%-18%-(H8*0.4%),IF(100%-18%+(H8*0.4%)>100%,100%,100%-18%+(H8*0.4%))),IF(COUNTIF(J9,"9.*"),(N40)*P11,IF(COUNTIF(J9,"10.*"),M44*P11,""))))))))))) | R11: =IF(COUNTIF(C7,""),"",Q11*O11)
C12: =IF(COUNTIF(A34,"1.*"),B12*D39,"") | E12: =IF(COUNTIF(E34,"1.*"),D12*H39,"") | G12: =IF(AND(COUNTIF(A34,"1.*"),COUNTIF(E34,"1.*")),SUM(A12*F12)-((C12*F12)+(E12*F12)),IF(COUNTIF(A34,"1.*"),SUM(A12*F12)-(C12*F12),IF(COUNTIF(E34,"1.*"),SUM(A12*F12)-(E12*F12),A12*F12))) -> 0 | H12: =IF(COUNTIF(A34,"1.*"),SUM(C12*F12),"") | I12: =IF(COUNTIF(E34,"1.*"),SUM(E12*F12),"") | J12: =IF(COUNTIF(J9,"2.*"),"","Full Benefit from 09/01/2011 to 09/30/2014:") -> Full Benefit from 09/01/2011 to 09/30/2014: | M12: =IF(COUNTIF(J9,"2.*"),"",SUM(A19:A20)) -> 3 | N12: =IF(COUNTIF(J9,"2.*"),"",SUM(A19*F19,A20*F20)) -> 375 | O12: =IF(COUNTIF(C7,""),"","13th Check") | P12: =IF(COUNTIF(C7,""),"",IF(COUNTIF(J9,"4.*"),IF(COUNTIF(I8,"*Younger*"),100%-8%-(H8*0.4%),IF(100%-8%+(H8*0.4%)>100%,100%,100%-8%+(H8*0.4%)))*100&"% / "&IF(COUNTIF(I8,"*Younger*"),100%-18%-(H8*0.4%),IF(100%-18%+(H8*0.4%)>100%,100%,100%-18%+(H8*0.4%)))*100&"%",IF(COUNTIF(J9,"6.*"),IF(COUNTIF(I8,"*Younger*"),100%-18%-(H8*0.4%),IF(100%-18%+(H8*0.4%)>100%,100%,100%-18%+(H8*0.4%))),IF(COUNTIF(J9,"8.*"),IF(COUNTIF(I8,"*Younger*"),100%-8%-(H8*0.4%),IF(100%-8%+(H8*0.4%)>100%,100%,100%-8%+(H8*0.4%)))*100&"% / "&IF(COUNTIF(I8,"*Younger*"),100%-18%-(H8*0.4%),IF(100%-18%+(H8*0.4%)>100%,100%,100%-18%+(H8*0.4%)))*100&"%",IF(COUNTIF(I8,"*Younger*"),100%-8%-(H8*0.4%),IF(100%-8%+(H8*0.4%)>100%,100%,100%-8%+(H8*0.4%))))))) | Q12: =IF(COUNTIF(C7,""),"",IF(COUNTIF(J9,"1.*"),(N41)*P12,IF(COUNTIF(J9,"2.*"),(N41)*P12,IF(COUNTIF(J9,"3.*"),(N41)*P12,IF(COUNTIF(J9,"5.*"),(N41)*P12,IF(COUNTIF(J9,"6.*"),(N41)*P12,IF(COUNTIF(J9,"7.*"),(N41)*P12,IF(COUNTIF(J9,"8.*"),(N11+N12)*IF(COUNTIF(I8,"*Younger*"),100%-8%-(H8*0.4%),IF(100%-8%+(H8*0.4%)>100%,100%,100%-8%+(H8*0.4%))),IF(COUNTIF(J9,"4.*"),N11*IF(COUNTIF(I8,"*Younger*"),100%-8%-(H8*0.4%),IF(100%-8%+(H8*0.4%)>100%,100%,100%-8%+(H8*0.4%)))+(N12)*IF(COUNTIF(I8,"*Younger*"),100%-18%-(H8*0.4%),IF(100%-18%+(H8*0.4%)>100%,100%,100%-18%+(H8*0.4%))),IF(COUNTIF(J9,"9.*"),(N41)*P12,IF(COUNTIF(J9,"10.*"),IF(COUNTIF(L44,"*1*"),M24*P12,M41*P12),""))))))))))) | R12: =IF(COUNTIF(C7,""),"",Q12*O11)
C13: =IF(COUNTIF(A34,"1.*"),B13*D39,"") | E13: =IF(COUNTIF(E34,"1.*"),D13*H39,"") | F13: 90 | G13: =IF(AND(COUNTIF(A34,"1.*"),COUNTIF(E34,"1.*")),SUM(A13*F13)-((C13*F13)+(E13*F13)),IF(COUNTIF(A34,"1.*"),SUM(A13*F13)-(C13*F13),IF(COUNTIF(E34,"1.*"),SUM(A13*F13)-(E13*F13),A13*F13))) -> 0 | H13: =IF(COUNTIF(A34,"1.*"),ROUND(C13*F13,2),"") | I13: =IF(COUNTIF(E34,"1.*"),SUM(E13*F13),"") | J13: =IF(COUNTIF(J9,"2.*"),"","Full Benefit on and After 10/01/2014:") -> Full Benefit on and After 10/01/2014: | M13: =IF(COUNTIF(J9,"2.*"),"",IF(COUNTIF(J9,"10.*"),SUM(A23:A25,A29:A31),SUM(A23:A25))) -> 12.5 | N13: =IF(COUNTIF(J9,"2.*"),"",IF(COUNTIF(J9,"10.*"),SUM(A23*F23,A24*F24,A25*F25,A29*F29,A30*F30,A31*F31),SUM(A23*F23,A24*F24,A25*F25))) -> 1687.5 | O13: =IF(COUNTIF(C7,""),"","75%") | P13: =IF(COUNTIF(C7,""),"",IF(COUNTIF(J9,"4.*"),IF(COUNTIF(I8,"*Younger*"),100%-12%-(H8*0.4%),IF(100%-12%+(H8*0.4%)>100%,100%,100%-12%+(H8*0.4%)))*100&"% / "&IF(COUNTIF(I8,"*Younger*"),100%-24%-(H8*0.4%),IF(100%-24%+(H8*0.4%)>100%,100%,100%-24%+(H8*0.4%)))*100&"%",IF(COUNTIF(J9,"6.*"),IF(COUNTIF(I8,"*Younger*"),100%-24%-(H8*0.4%),IF(100%-24%+(H8*0.4%)>100%,100%,100%-24%+(H8*0.4%))),IF(COUNTIF(J9,"8.*"),IF(COUNTIF(I8,"*Younger*"),100%-12%-(H8*0.4%),IF(100%-12%+(H8*0.4%)>100%,100%,100%-12%+(H8*0.4%)))*100&"% / "&IF(COUNTIF(I8,"*Younger*"),100%-24%-(H8*0.4%),IF(100%-24%+(H8*0.4%)>100%,100%,100%-24%+(H8*0.4%)))*100&"%",IF(COUNTIF(I8,"*Younger*"),100%-12%-(H8*0.4%),IF(100%-12%+(H8*0.4%)>100%,100%,100%-12%+(H8*0.4%))))))) | Q13: =IF(COUNTIF(C7,""),"",IF(COUNTIF(J9,"1.*"),(N40)*P13,IF(COUNTIF(J9,"2.*"),(N40)*P13,IF(COUNTIF(J9,"3.*"),(N40)*P13,IF(COUNTIF(J9,"5.*"),(N40)*P13,IF(COUNTIF(J9,"6.*"),(N40)*P13,IF(COUNTIF(J9,"7.*"),(N40)*P13,IF(COUNTIF(J9,"8.*"),(N11+N12)*IF(COUNTIF(I8,"*Younger*"),100%-12%-(H8*0.4%),IF(100%-12%+(H8*0.4%)>100%,100%,100%-12%+(H8*0.4%)))+(N13*IF(COUNTIF(I8,"*Younger*"),100%-24%-(H8*0.4%),IF(100%-24%+(H8*0.4%)>100%,100%,100%-24%+(H8*0.4%)))),IF(COUNTIF(J9,"4.*"),N11*IF(COUNTIF(I8,"*Younger*"),100%-12%-(H8*0.4%),IF(100%-12%+(H8*0.4%)>100%,100%,100%-12%+(H8*0.4%)))+(N12+N13)*IF(COUNTIF(I8,"*Younger*"),100%-24%-(H8*0.4%),IF(100%-24%+(H8*0.4%)>100%,100%,100%-24%+(H8*0.4%))),IF(COUNTIF(J9,"9.*"),(N40)*P13,IF(COUNTIF(J9,"10.*"),M44*P13,""))))))))))) | R13: =IF(COUNTIF(C7,""),"",Q13*O13)
A14: 12.84 | C14: =IF(COUNTIF(A34,"1.*"),B14*D39,"") | E14: =IF(COUNTIF(E34,"1.*"),D14*H39,"") | F14: 118 | G14: =IF(AND(COUNTIF(A34,"1.*"),COUNTIF(E34,"1.*")),ROUND(A14*F14,2)-(ROUND(C14*F14,2)+ROUND(E14*F14,2)),IF(COUNTIF(A34,"1.*"),ROUND(A14*F14,2)-ROUND(C14*F14,2),IF(COUNTIF(E34,"1.*"),ROUND(A14*F14,2)-ROUND(E14*F14,2),ROUND(A14*F14,2)))) -> 1515.12 | H14: =IF(COUNTIF(A34,"1.*"),ROUND(C14*F14,2),"") | I14: =IF(COUNTIF(E34,"1.*"),SUM(E14*F14),"") | J14: Total Pension Credits & Amount: | M14: =SUM(M11:M13) -> 31.01 | N14: =SUM(N11:N13) -> 3911.37 | O14: =IF(COUNTIF(C7,""),"","13th Check") | P14: =IF(COUNTIF(C7,""),"",IF(COUNTIF(J9,"4.*"),IF(COUNTIF(I8,"*Younger*"),100%-12%-(H8*0.4%),IF(100%-12%+(H8*0.4%)>100%,100%,100%-12%+(H8*0.4%)))*100&"% / "&IF(COUNTIF(I8,"*Younger*"),100%-24%-(H8*0.4%),IF(100%-24%+(H8*0.4%)>100%,100%,100%-24%+(H8*0.4%)))*100&"%",IF(COUNTIF(J9,"6.*"),IF(COUNTIF(I8,"*Younger*"),100%-24%-(H8*0.4%),IF(100%-24%+(H8*0.4%)>100%,100%,100%-24%+(H8*0.4%))),IF(COUNTIF(J9,"8.*"),IF(COUNTIF(I8,"*Younger*"),100%-12%-(H8*0.4%),IF(100%-12%+(H8*0.4%)>100%,100%,100%-12%+(H8*0.4%)))*100&"% / "&IF(COUNTIF(I8,"*Younger*"),100%-24%-(H8*0.4%),IF(100%-24%+(H8*0.4%)>100%,100%,100%-24%+(H8*0.4%)))*100&"%",IF(COUNTIF(I8,"*Younger*"),100%-12%-(H8*0.4%),IF(100%-12%+(H8*0.4%)>100%,100%,100%-12%+(H8*0.4%))))))) | Q14: =IF(COUNTIF(C7,""),"",IF(COUNTIF(J9,"1.*"),(N41)*P14,IF(COUNTIF(J9,"2.*"),(N41)*P14,IF(COUNTIF(J9,"3.*"),(N41)*P14,IF(COUNTIF(J9,"5.*"),(N41)*P14,IF(COUNTIF(J9,"6.*"),(N41)*P14,IF(COUNTIF(J9,"7.*"),(N41)*P14,IF(COUNTIF(J9,"8.*"),(N11+N12)*IF(COUNTIF(I8,"*Younger*"),100%-12%-(H8*0.4%),IF(100%-12%+(H8*0.4%)>100%,100%,100%-12%+(H8*0.4%))),IF(COUNTIF(J9,"4.*"),N11*IF(COUNTIF(I8,"*Younger*"),100%-12%-(H8*0.4%),IF(100%-12%+(H8*0.4%)>100%,100%,100%-12%+(H8*0.4%)))+(N12)*IF(COUNTIF(I8,"*Younger*"),100%-24%-(H8*0.4%),IF(100%-24%+(H8*0.4%)>100%,100%,100%-24%+(H8*0.4%))),IF(COUNTIF(J9,"9.*"),(N41)*P14,IF(COUNTIF(J9,"10.*"),IF(COUNTIF(L44,"*1*"),M24*P14,M41*P14),""))))))))))) | R14: =IF(COUNTIF(C7,""),"",Q14*O13)
C15: =IF(COUNTIF(A34,"1.*"),B15*D39,"") | E15: =IF(COUNTIF(E34,"1.*"),D15*H39,"") | F15: 105 | G15: =IF(AND(COUNTIF(A34,"1.*"),COUNTIF(E34,"1.*")),ROUND(A15*F15,2)-(ROUND(C15*F15,2)+ROUND(E15*F15,2)),IF(COUNTIF(A34,"1.*"),ROUND(A15*F15,2)-ROUND(C15*F15,2),IF(COUNTIF(E34,"1.*"),ROUND(A15*F15,2)-ROUND(E15*F15,2),ROUND(A15*F15,2)))) -> 0 | H15: =IF(COUNTIF(A34,"1.*"),ROUND(C15*F15,2),"") | I15: =IF(COUNTIF(E34,"1.*"),SUM(E15*F15),"") | J15: =IF(COUNTIF(J9,"10.*"),"Delayed Retirement Calculation 1","") | O15: =IF(COUNTIF(C7,""),"","100%") | P15: =IF(COUNTIF(C7,""),"",IF(COUNTIF(J9,"4.*"),IF(COUNTIF(I8,"*Younger*"),100%-15%-(H8*0.5%),IF(100%-15%+(H8*0.5%)>100%,100%,100%-15%+(H8*0.5%)))*100&"% / "&IF(COUNTIF(I8,"*Younger*"),100%-30%-(H8*0.5%),IF(100%-30%+(H8*0.5%)>100%,100%,100%-30%+(H8*0.5%)))*100&"%",IF(COUNTIF(J9,"6.*"),IF(COUNTIF(I8,"*Younger*"),100%-30%-(H8*0.5%),IF(100%-30%+(H8*0.5%)>100%,100%,100%-30%+(H8*0.5%))),IF(COUNTIF(J9,"8.*"),IF(COUNTIF(I8,"*Younger*"),100%-15%-(H8*0.5%),IF(100%-15%+(H8*0.5%)>100%,100%,100%-15%+(H8*0.5%)))*100&"% / "&IF(COUNTIF(I8,"*Younger*"),100%-30%-(H8*0.5%),IF(100%-30%+(H8*0.5%)>100%,100%,100%-30%+(H8*0.5%)))*100&"%",IF(COUNTIF(I8,"*Younger*"),100%-15%-(H8*0.5%),IF(100%-15%+(H8*0.5%)>100%,100%,100%-15%+(H8*0.5%))))))) | Q15: =IF(COUNTIF(C7,""),"",IF(COUNTIF(J9,"1.*"),(N40)*P15,IF(COUNTIF(J9,"2.*"),(N40)*P15,IF(COUNTIF(J9,"3.*"),(N40)*P15,IF(COUNTIF(J9,"5.*"),(N40)*P15,IF(COUNTIF(J9,"6.*"),(N40)*P15,IF(COUNTIF(J9,"7.*"),(N40)*P15,IF(COUNTIF(J9,"8.*"),(N11+N12)*IF(COUNTIF(I8,"*Younger*"),100%-15%-(H8*0.5%),IF(100%-15%+(H8*0.5%)>100%,100%,100%-15%+(H8*0.5%)))+(N13*IF(COUNTIF(I8,"*Younger*"),100%-30%-(H8*0.5%),IF(100%-30%+(H8*0.5%)>100%,100%,100%-30%+(H8*0.5%)))),IF(COUNTIF(J9,"4.*"),N11*IF(COUNTIF(I8,"*Younger*"),100%-15%-(H8*0.5%),IF(100%-15%+(H8*0.5%)>100%,100%,100%-15%+(H8*0.5%)))+(N12+N13)*IF(COUNTIF(I8,"*Younger*"),100%-30%-(H8*0.5%),IF(100%-30%+(H8*0.5%)>100%,100%,100%-30%+(H8*0.5%))),IF(COUNTIF(J9,"9.*"),(N40)*P15,IF(COUNTIF(J9,"10.*"),M44*P15,""))))))))))) | R15: =IF(COUNTIF(C7,""),"",Q15*O15)
